[2023-03-13 01:35:35] [INFO    ] discord.client: logging in using static token
[2023-03-13 01:35:36] [INFO    ] discord.gateway: Shard ID None has connected to Gateway (Session ID: 83be45b2b4cbe00eb01d0d155a0fcb96).
[2023-03-13 04:38:59] [INFO    ] discord.gateway: Shard ID None has successfully RESUMED session 83be45b2b4cbe00eb01d0d155a0fcb96.
[2023-03-13 06:43:06] [INFO    ] discord.gateway: Shard ID None has successfully RESUMED session 83be45b2b4cbe00eb01d0d155a0fcb96.
[2023-03-13 08:49:56] [INFO    ] discord.client: logging in using static token
[2023-03-13 08:49:57] [INFO    ] discord.gateway: Shard ID None has connected to Gateway (Session ID: a171394775a98564408c8a906a7881b9).
[2023-03-13 11:17:32] [ERROR   ] discord.client: Attempting a reconnect in 0.11s
Traceback (most recent call last):
  File "/home/itjeong/.local/lib/python3.8/site-packages/aiohttp/connector.py", line 1152, in _create_direct_connection
    hosts = await asyncio.shield(host_resolved)
  File "/home/itjeong/.local/lib/python3.8/site-packages/aiohttp/connector.py", line 874, in _resolve_host
    addrs = await self._resolver.resolve(host, port, family=self._family)
  File "/home/itjeong/.local/lib/python3.8/site-packages/aiohttp/resolver.py", line 33, in resolve
    infos = await self._loop.getaddrinfo(
  File "/usr/lib/python3.8/asyncio/base_events.py", line 825, in getaddrinfo
    return await self.run_in_executor(
  File "/usr/lib/python3.8/concurrent/futures/thread.py", line 57, in run
    result = self.fn(*self.args, **self.kwargs)
  File "/usr/lib/python3.8/socket.py", line 918, in getaddrinfo
    for res in _socket.getaddrinfo(host, port, family, type, proto, flags):
socket.gaierror: [Errno -3] Temporary failure in name resolution

The above exception was the direct cause of the following exception:

Traceback (most recent call last):
  File "/home/itjeong/.local/lib/python3.8/site-packages/discord/client.py", line 656, in connect
    self.ws = await asyncio.wait_for(coro, timeout=60.0)
  File "/usr/lib/python3.8/asyncio/tasks.py", line 494, in wait_for
    return fut.result()
  File "/home/itjeong/.local/lib/python3.8/site-packages/discord/gateway.py", line 372, in from_client
    socket = await client.http.ws_connect(str(url))
  File "/home/itjeong/.local/lib/python3.8/site-packages/discord/http.py", line 536, in ws_connect
    return await self.__session.ws_connect(url, **kwargs)
  File "/home/itjeong/.local/lib/python3.8/site-packages/aiohttp/client.py", line 779, in _ws_connect
    resp = await self.request(
  File "/home/itjeong/.local/lib/python3.8/site-packages/aiohttp/client.py", line 536, in _request
    conn = await self._connector.connect(
  File "/home/itjeong/.local/lib/python3.8/site-packages/aiohttp/connector.py", line 540, in connect
    proto = await self._create_connection(req, traces, timeout)
  File "/home/itjeong/.local/lib/python3.8/site-packages/aiohttp/connector.py", line 901, in _create_connection
    _, proto = await self._create_direct_connection(req, traces, timeout)
  File "/home/itjeong/.local/lib/python3.8/site-packages/aiohttp/connector.py", line 1166, in _create_direct_connection
    raise ClientConnectorError(req.connection_key, exc) from exc
aiohttp.client_exceptions.ClientConnectorError: Cannot connect to host gateway-us-east1-c.discord.gg:443 ssl:default [Temporary failure in name resolution]
[2023-03-13 11:17:42] [ERROR   ] discord.client: Attempting a reconnect in 1.12s
Traceback (most recent call last):
  File "/home/itjeong/.local/lib/python3.8/site-packages/aiohttp/connector.py", line 1152, in _create_direct_connection
    hosts = await asyncio.shield(host_resolved)
  File "/home/itjeong/.local/lib/python3.8/site-packages/aiohttp/connector.py", line 874, in _resolve_host
    addrs = await self._resolver.resolve(host, port, family=self._family)
  File "/home/itjeong/.local/lib/python3.8/site-packages/aiohttp/resolver.py", line 33, in resolve
    infos = await self._loop.getaddrinfo(
  File "/usr/lib/python3.8/asyncio/base_events.py", line 825, in getaddrinfo
    return await self.run_in_executor(
  File "/usr/lib/python3.8/concurrent/futures/thread.py", line 57, in run
    result = self.fn(*self.args, **self.kwargs)
  File "/usr/lib/python3.8/socket.py", line 918, in getaddrinfo
    for res in _socket.getaddrinfo(host, port, family, type, proto, flags):
socket.gaierror: [Errno -3] Temporary failure in name resolution

The above exception was the direct cause of the following exception:

Traceback (most recent call last):
  File "/home/itjeong/.local/lib/python3.8/site-packages/discord/client.py", line 656, in connect
    self.ws = await asyncio.wait_for(coro, timeout=60.0)
  File "/usr/lib/python3.8/asyncio/tasks.py", line 494, in wait_for
    return fut.result()
  File "/home/itjeong/.local/lib/python3.8/site-packages/discord/gateway.py", line 372, in from_client
    socket = await client.http.ws_connect(str(url))
  File "/home/itjeong/.local/lib/python3.8/site-packages/discord/http.py", line 536, in ws_connect
    return await self.__session.ws_connect(url, **kwargs)
  File "/home/itjeong/.local/lib/python3.8/site-packages/aiohttp/client.py", line 779, in _ws_connect
    resp = await self.request(
  File "/home/itjeong/.local/lib/python3.8/site-packages/aiohttp/client.py", line 536, in _request
    conn = await self._connector.connect(
  File "/home/itjeong/.local/lib/python3.8/site-packages/aiohttp/connector.py", line 540, in connect
    proto = await self._create_connection(req, traces, timeout)
  File "/home/itjeong/.local/lib/python3.8/site-packages/aiohttp/connector.py", line 901, in _create_connection
    _, proto = await self._create_direct_connection(req, traces, timeout)
  File "/home/itjeong/.local/lib/python3.8/site-packages/aiohttp/connector.py", line 1166, in _create_direct_connection
    raise ClientConnectorError(req.connection_key, exc) from exc
aiohttp.client_exceptions.ClientConnectorError: Cannot connect to host gateway-us-east1-c.discord.gg:443 ssl:default [Temporary failure in name resolution]
[2023-03-13 11:17:53] [ERROR   ] discord.client: Attempting a reconnect in 1.74s
Traceback (most recent call last):
  File "/home/itjeong/.local/lib/python3.8/site-packages/aiohttp/connector.py", line 1152, in _create_direct_connection
    hosts = await asyncio.shield(host_resolved)
  File "/home/itjeong/.local/lib/python3.8/site-packages/aiohttp/connector.py", line 874, in _resolve_host
    addrs = await self._resolver.resolve(host, port, family=self._family)
  File "/home/itjeong/.local/lib/python3.8/site-packages/aiohttp/resolver.py", line 33, in resolve
    infos = await self._loop.getaddrinfo(
  File "/usr/lib/python3.8/asyncio/base_events.py", line 825, in getaddrinfo
    return await self.run_in_executor(
  File "/usr/lib/python3.8/concurrent/futures/thread.py", line 57, in run
    result = self.fn(*self.args, **self.kwargs)
  File "/usr/lib/python3.8/socket.py", line 918, in getaddrinfo
    for res in _socket.getaddrinfo(host, port, family, type, proto, flags):
socket.gaierror: [Errno -3] Temporary failure in name resolution

The above exception was the direct cause of the following exception:

Traceback (most recent call last):
  File "/home/itjeong/.local/lib/python3.8/site-packages/discord/client.py", line 656, in connect
    self.ws = await asyncio.wait_for(coro, timeout=60.0)
  File "/usr/lib/python3.8/asyncio/tasks.py", line 494, in wait_for
    return fut.result()
  File "/home/itjeong/.local/lib/python3.8/site-packages/discord/gateway.py", line 372, in from_client
    socket = await client.http.ws_connect(str(url))
  File "/home/itjeong/.local/lib/python3.8/site-packages/discord/http.py", line 536, in ws_connect
    return await self.__session.ws_connect(url, **kwargs)
  File "/home/itjeong/.local/lib/python3.8/site-packages/aiohttp/client.py", line 779, in _ws_connect
    resp = await self.request(
  File "/home/itjeong/.local/lib/python3.8/site-packages/aiohttp/client.py", line 536, in _request
    conn = await self._connector.connect(
  File "/home/itjeong/.local/lib/python3.8/site-packages/aiohttp/connector.py", line 540, in connect
    proto = await self._create_connection(req, traces, timeout)
  File "/home/itjeong/.local/lib/python3.8/site-packages/aiohttp/connector.py", line 901, in _create_connection
    _, proto = await self._create_direct_connection(req, traces, timeout)
  File "/home/itjeong/.local/lib/python3.8/site-packages/aiohttp/connector.py", line 1166, in _create_direct_connection
    raise ClientConnectorError(req.connection_key, exc) from exc
aiohttp.client_exceptions.ClientConnectorError: Cannot connect to host gateway-us-east1-c.discord.gg:443 ssl:default [Temporary failure in name resolution]
[2023-03-13 11:18:05] [ERROR   ] discord.client: Attempting a reconnect in 12.33s
Traceback (most recent call last):
  File "/home/itjeong/.local/lib/python3.8/site-packages/aiohttp/connector.py", line 1152, in _create_direct_connection
    hosts = await asyncio.shield(host_resolved)
  File "/home/itjeong/.local/lib/python3.8/site-packages/aiohttp/connector.py", line 874, in _resolve_host
    addrs = await self._resolver.resolve(host, port, family=self._family)
  File "/home/itjeong/.local/lib/python3.8/site-packages/aiohttp/resolver.py", line 33, in resolve
    infos = await self._loop.getaddrinfo(
  File "/usr/lib/python3.8/asyncio/base_events.py", line 825, in getaddrinfo
    return await self.run_in_executor(
  File "/usr/lib/python3.8/concurrent/futures/thread.py", line 57, in run
    result = self.fn(*self.args, **self.kwargs)
  File "/usr/lib/python3.8/socket.py", line 918, in getaddrinfo
    for res in _socket.getaddrinfo(host, port, family, type, proto, flags):
socket.gaierror: [Errno -3] Temporary failure in name resolution

The above exception was the direct cause of the following exception:

Traceback (most recent call last):
  File "/home/itjeong/.local/lib/python3.8/site-packages/discord/client.py", line 656, in connect
    self.ws = await asyncio.wait_for(coro, timeout=60.0)
  File "/usr/lib/python3.8/asyncio/tasks.py", line 494, in wait_for
    return fut.result()
  File "/home/itjeong/.local/lib/python3.8/site-packages/discord/gateway.py", line 372, in from_client
    socket = await client.http.ws_connect(str(url))
  File "/home/itjeong/.local/lib/python3.8/site-packages/discord/http.py", line 536, in ws_connect
    return await self.__session.ws_connect(url, **kwargs)
  File "/home/itjeong/.local/lib/python3.8/site-packages/aiohttp/client.py", line 779, in _ws_connect
    resp = await self.request(
  File "/home/itjeong/.local/lib/python3.8/site-packages/aiohttp/client.py", line 536, in _request
    conn = await self._connector.connect(
  File "/home/itjeong/.local/lib/python3.8/site-packages/aiohttp/connector.py", line 540, in connect
    proto = await self._create_connection(req, traces, timeout)
  File "/home/itjeong/.local/lib/python3.8/site-packages/aiohttp/connector.py", line 901, in _create_connection
    _, proto = await self._create_direct_connection(req, traces, timeout)
  File "/home/itjeong/.local/lib/python3.8/site-packages/aiohttp/connector.py", line 1166, in _create_direct_connection
    raise ClientConnectorError(req.connection_key, exc) from exc
aiohttp.client_exceptions.ClientConnectorError: Cannot connect to host gateway-us-east1-c.discord.gg:443 ssl:default [Temporary failure in name resolution]
[2023-03-13 11:18:28] [ERROR   ] discord.client: Attempting a reconnect in 26.07s
Traceback (most recent call last):
  File "/home/itjeong/.local/lib/python3.8/site-packages/aiohttp/connector.py", line 1152, in _create_direct_connection
    hosts = await asyncio.shield(host_resolved)
  File "/home/itjeong/.local/lib/python3.8/site-packages/aiohttp/connector.py", line 874, in _resolve_host
    addrs = await self._resolver.resolve(host, port, family=self._family)
  File "/home/itjeong/.local/lib/python3.8/site-packages/aiohttp/resolver.py", line 33, in resolve
    infos = await self._loop.getaddrinfo(
  File "/usr/lib/python3.8/asyncio/base_events.py", line 825, in getaddrinfo
    return await self.run_in_executor(
  File "/usr/lib/python3.8/concurrent/futures/thread.py", line 57, in run
    result = self.fn(*self.args, **self.kwargs)
  File "/usr/lib/python3.8/socket.py", line 918, in getaddrinfo
    for res in _socket.getaddrinfo(host, port, family, type, proto, flags):
socket.gaierror: [Errno -3] Temporary failure in name resolution

The above exception was the direct cause of the following exception:

Traceback (most recent call last):
  File "/home/itjeong/.local/lib/python3.8/site-packages/discord/client.py", line 656, in connect
    self.ws = await asyncio.wait_for(coro, timeout=60.0)
  File "/usr/lib/python3.8/asyncio/tasks.py", line 494, in wait_for
    return fut.result()
  File "/home/itjeong/.local/lib/python3.8/site-packages/discord/gateway.py", line 372, in from_client
    socket = await client.http.ws_connect(str(url))
  File "/home/itjeong/.local/lib/python3.8/site-packages/discord/http.py", line 536, in ws_connect
    return await self.__session.ws_connect(url, **kwargs)
  File "/home/itjeong/.local/lib/python3.8/site-packages/aiohttp/client.py", line 779, in _ws_connect
    resp = await self.request(
  File "/home/itjeong/.local/lib/python3.8/site-packages/aiohttp/client.py", line 536, in _request
    conn = await self._connector.connect(
  File "/home/itjeong/.local/lib/python3.8/site-packages/aiohttp/connector.py", line 540, in connect
    proto = await self._create_connection(req, traces, timeout)
  File "/home/itjeong/.local/lib/python3.8/site-packages/aiohttp/connector.py", line 901, in _create_connection
    _, proto = await self._create_direct_connection(req, traces, timeout)
  File "/home/itjeong/.local/lib/python3.8/site-packages/aiohttp/connector.py", line 1166, in _create_direct_connection
    raise ClientConnectorError(req.connection_key, exc) from exc
aiohttp.client_exceptions.ClientConnectorError: Cannot connect to host gateway-us-east1-c.discord.gg:443 ssl:default [Temporary failure in name resolution]
[2023-03-13 11:19:04] [ERROR   ] discord.client: Attempting a reconnect in 62.95s
Traceback (most recent call last):
  File "/home/itjeong/.local/lib/python3.8/site-packages/aiohttp/connector.py", line 1152, in _create_direct_connection
    hosts = await asyncio.shield(host_resolved)
  File "/home/itjeong/.local/lib/python3.8/site-packages/aiohttp/connector.py", line 874, in _resolve_host
    addrs = await self._resolver.resolve(host, port, family=self._family)
  File "/home/itjeong/.local/lib/python3.8/site-packages/aiohttp/resolver.py", line 33, in resolve
    infos = await self._loop.getaddrinfo(
  File "/usr/lib/python3.8/asyncio/base_events.py", line 825, in getaddrinfo
    return await self.run_in_executor(
  File "/usr/lib/python3.8/concurrent/futures/thread.py", line 57, in run
    result = self.fn(*self.args, **self.kwargs)
  File "/usr/lib/python3.8/socket.py", line 918, in getaddrinfo
    for res in _socket.getaddrinfo(host, port, family, type, proto, flags):
socket.gaierror: [Errno -3] Temporary failure in name resolution

The above exception was the direct cause of the following exception:

Traceback (most recent call last):
  File "/home/itjeong/.local/lib/python3.8/site-packages/discord/client.py", line 656, in connect
    self.ws = await asyncio.wait_for(coro, timeout=60.0)
  File "/usr/lib/python3.8/asyncio/tasks.py", line 494, in wait_for
    return fut.result()
  File "/home/itjeong/.local/lib/python3.8/site-packages/discord/gateway.py", line 372, in from_client
    socket = await client.http.ws_connect(str(url))
  File "/home/itjeong/.local/lib/python3.8/site-packages/discord/http.py", line 536, in ws_connect
    return await self.__session.ws_connect(url, **kwargs)
  File "/home/itjeong/.local/lib/python3.8/site-packages/aiohttp/client.py", line 779, in _ws_connect
    resp = await self.request(
  File "/home/itjeong/.local/lib/python3.8/site-packages/aiohttp/client.py", line 536, in _request
    conn = await self._connector.connect(
  File "/home/itjeong/.local/lib/python3.8/site-packages/aiohttp/connector.py", line 540, in connect
    proto = await self._create_connection(req, traces, timeout)
  File "/home/itjeong/.local/lib/python3.8/site-packages/aiohttp/connector.py", line 901, in _create_connection
    _, proto = await self._create_direct_connection(req, traces, timeout)
  File "/home/itjeong/.local/lib/python3.8/site-packages/aiohttp/connector.py", line 1166, in _create_direct_connection
    raise ClientConnectorError(req.connection_key, exc) from exc
aiohttp.client_exceptions.ClientConnectorError: Cannot connect to host gateway-us-east1-c.discord.gg:443 ssl:default [Temporary failure in name resolution]
[2023-03-13 11:20:17] [ERROR   ] discord.client: Attempting a reconnect in 13.76s
Traceback (most recent call last):
  File "/home/itjeong/.local/lib/python3.8/site-packages/aiohttp/connector.py", line 1152, in _create_direct_connection
    hosts = await asyncio.shield(host_resolved)
  File "/home/itjeong/.local/lib/python3.8/site-packages/aiohttp/connector.py", line 874, in _resolve_host
    addrs = await self._resolver.resolve(host, port, family=self._family)
  File "/home/itjeong/.local/lib/python3.8/site-packages/aiohttp/resolver.py", line 33, in resolve
    infos = await self._loop.getaddrinfo(
  File "/usr/lib/python3.8/asyncio/base_events.py", line 825, in getaddrinfo
    return await self.run_in_executor(
  File "/usr/lib/python3.8/concurrent/futures/thread.py", line 57, in run
    result = self.fn(*self.args, **self.kwargs)
  File "/usr/lib/python3.8/socket.py", line 918, in getaddrinfo
    for res in _socket.getaddrinfo(host, port, family, type, proto, flags):
socket.gaierror: [Errno -3] Temporary failure in name resolution

The above exception was the direct cause of the following exception:

Traceback (most recent call last):
  File "/home/itjeong/.local/lib/python3.8/site-packages/discord/client.py", line 656, in connect
    self.ws = await asyncio.wait_for(coro, timeout=60.0)
  File "/usr/lib/python3.8/asyncio/tasks.py", line 494, in wait_for
    return fut.result()
  File "/home/itjeong/.local/lib/python3.8/site-packages/discord/gateway.py", line 372, in from_client
    socket = await client.http.ws_connect(str(url))
  File "/home/itjeong/.local/lib/python3.8/site-packages/discord/http.py", line 536, in ws_connect
    return await self.__session.ws_connect(url, **kwargs)
  File "/home/itjeong/.local/lib/python3.8/site-packages/aiohttp/client.py", line 779, in _ws_connect
    resp = await self.request(
  File "/home/itjeong/.local/lib/python3.8/site-packages/aiohttp/client.py", line 536, in _request
    conn = await self._connector.connect(
  File "/home/itjeong/.local/lib/python3.8/site-packages/aiohttp/connector.py", line 540, in connect
    proto = await self._create_connection(req, traces, timeout)
  File "/home/itjeong/.local/lib/python3.8/site-packages/aiohttp/connector.py", line 901, in _create_connection
    _, proto = await self._create_direct_connection(req, traces, timeout)
  File "/home/itjeong/.local/lib/python3.8/site-packages/aiohttp/connector.py", line 1166, in _create_direct_connection
    raise ClientConnectorError(req.connection_key, exc) from exc
aiohttp.client_exceptions.ClientConnectorError: Cannot connect to host gateway-us-east1-c.discord.gg:443 ssl:default [Temporary failure in name resolution]
[2023-03-13 11:20:40] [ERROR   ] discord.client: Attempting a reconnect in 106.86s
Traceback (most recent call last):
  File "/home/itjeong/.local/lib/python3.8/site-packages/aiohttp/connector.py", line 1152, in _create_direct_connection
    hosts = await asyncio.shield(host_resolved)
  File "/home/itjeong/.local/lib/python3.8/site-packages/aiohttp/connector.py", line 874, in _resolve_host
    addrs = await self._resolver.resolve(host, port, family=self._family)
  File "/home/itjeong/.local/lib/python3.8/site-packages/aiohttp/resolver.py", line 33, in resolve
    infos = await self._loop.getaddrinfo(
  File "/usr/lib/python3.8/asyncio/base_events.py", line 825, in getaddrinfo
    return await self.run_in_executor(
  File "/usr/lib/python3.8/concurrent/futures/thread.py", line 57, in run
    result = self.fn(*self.args, **self.kwargs)
  File "/usr/lib/python3.8/socket.py", line 918, in getaddrinfo
    for res in _socket.getaddrinfo(host, port, family, type, proto, flags):
socket.gaierror: [Errno -3] Temporary failure in name resolution

The above exception was the direct cause of the following exception:

Traceback (most recent call last):
  File "/home/itjeong/.local/lib/python3.8/site-packages/discord/client.py", line 656, in connect
    self.ws = await asyncio.wait_for(coro, timeout=60.0)
  File "/usr/lib/python3.8/asyncio/tasks.py", line 494, in wait_for
    return fut.result()
  File "/home/itjeong/.local/lib/python3.8/site-packages/discord/gateway.py", line 372, in from_client
    socket = await client.http.ws_connect(str(url))
  File "/home/itjeong/.local/lib/python3.8/site-packages/discord/http.py", line 536, in ws_connect
    return await self.__session.ws_connect(url, **kwargs)
  File "/home/itjeong/.local/lib/python3.8/site-packages/aiohttp/client.py", line 779, in _ws_connect
    resp = await self.request(
  File "/home/itjeong/.local/lib/python3.8/site-packages/aiohttp/client.py", line 536, in _request
    conn = await self._connector.connect(
  File "/home/itjeong/.local/lib/python3.8/site-packages/aiohttp/connector.py", line 540, in connect
    proto = await self._create_connection(req, traces, timeout)
  File "/home/itjeong/.local/lib/python3.8/site-packages/aiohttp/connector.py", line 901, in _create_connection
    _, proto = await self._create_direct_connection(req, traces, timeout)
  File "/home/itjeong/.local/lib/python3.8/site-packages/aiohttp/connector.py", line 1166, in _create_direct_connection
    raise ClientConnectorError(req.connection_key, exc) from exc
aiohttp.client_exceptions.ClientConnectorError: Cannot connect to host gateway-us-east1-c.discord.gg:443 ssl:default [Temporary failure in name resolution]
[2023-03-13 11:22:37] [ERROR   ] discord.client: Attempting a reconnect in 301.68s
Traceback (most recent call last):
  File "/home/itjeong/.local/lib/python3.8/site-packages/aiohttp/connector.py", line 1152, in _create_direct_connection
    hosts = await asyncio.shield(host_resolved)
  File "/home/itjeong/.local/lib/python3.8/site-packages/aiohttp/connector.py", line 874, in _resolve_host
    addrs = await self._resolver.resolve(host, port, family=self._family)
  File "/home/itjeong/.local/lib/python3.8/site-packages/aiohttp/resolver.py", line 33, in resolve
    infos = await self._loop.getaddrinfo(
  File "/usr/lib/python3.8/asyncio/base_events.py", line 825, in getaddrinfo
    return await self.run_in_executor(
  File "/usr/lib/python3.8/concurrent/futures/thread.py", line 57, in run
    result = self.fn(*self.args, **self.kwargs)
  File "/usr/lib/python3.8/socket.py", line 918, in getaddrinfo
    for res in _socket.getaddrinfo(host, port, family, type, proto, flags):
socket.gaierror: [Errno -3] Temporary failure in name resolution

The above exception was the direct cause of the following exception:

Traceback (most recent call last):
  File "/home/itjeong/.local/lib/python3.8/site-packages/discord/client.py", line 656, in connect
    self.ws = await asyncio.wait_for(coro, timeout=60.0)
  File "/usr/lib/python3.8/asyncio/tasks.py", line 494, in wait_for
    return fut.result()
  File "/home/itjeong/.local/lib/python3.8/site-packages/discord/gateway.py", line 372, in from_client
    socket = await client.http.ws_connect(str(url))
  File "/home/itjeong/.local/lib/python3.8/site-packages/discord/http.py", line 536, in ws_connect
    return await self.__session.ws_connect(url, **kwargs)
  File "/home/itjeong/.local/lib/python3.8/site-packages/aiohttp/client.py", line 779, in _ws_connect
    resp = await self.request(
  File "/home/itjeong/.local/lib/python3.8/site-packages/aiohttp/client.py", line 536, in _request
    conn = await self._connector.connect(
  File "/home/itjeong/.local/lib/python3.8/site-packages/aiohttp/connector.py", line 540, in connect
    proto = await self._create_connection(req, traces, timeout)
  File "/home/itjeong/.local/lib/python3.8/site-packages/aiohttp/connector.py", line 901, in _create_connection
    _, proto = await self._create_direct_connection(req, traces, timeout)
  File "/home/itjeong/.local/lib/python3.8/site-packages/aiohttp/connector.py", line 1166, in _create_direct_connection
    raise ClientConnectorError(req.connection_key, exc) from exc
aiohttp.client_exceptions.ClientConnectorError: Cannot connect to host gateway-us-east1-c.discord.gg:443 ssl:default [Temporary failure in name resolution]
[2023-03-13 11:27:49] [ERROR   ] discord.client: Attempting a reconnect in 884.34s
Traceback (most recent call last):
  File "/home/itjeong/.local/lib/python3.8/site-packages/aiohttp/connector.py", line 1152, in _create_direct_connection
    hosts = await asyncio.shield(host_resolved)
  File "/home/itjeong/.local/lib/python3.8/site-packages/aiohttp/connector.py", line 874, in _resolve_host
    addrs = await self._resolver.resolve(host, port, family=self._family)
  File "/home/itjeong/.local/lib/python3.8/site-packages/aiohttp/resolver.py", line 33, in resolve
    infos = await self._loop.getaddrinfo(
  File "/usr/lib/python3.8/asyncio/base_events.py", line 825, in getaddrinfo
    return await self.run_in_executor(
  File "/usr/lib/python3.8/concurrent/futures/thread.py", line 57, in run
    result = self.fn(*self.args, **self.kwargs)
  File "/usr/lib/python3.8/socket.py", line 918, in getaddrinfo
    for res in _socket.getaddrinfo(host, port, family, type, proto, flags):
socket.gaierror: [Errno -3] Temporary failure in name resolution

The above exception was the direct cause of the following exception:

Traceback (most recent call last):
  File "/home/itjeong/.local/lib/python3.8/site-packages/discord/client.py", line 656, in connect
    self.ws = await asyncio.wait_for(coro, timeout=60.0)
  File "/usr/lib/python3.8/asyncio/tasks.py", line 494, in wait_for
    return fut.result()
  File "/home/itjeong/.local/lib/python3.8/site-packages/discord/gateway.py", line 372, in from_client
    socket = await client.http.ws_connect(str(url))
  File "/home/itjeong/.local/lib/python3.8/site-packages/discord/http.py", line 536, in ws_connect
    return await self.__session.ws_connect(url, **kwargs)
  File "/home/itjeong/.local/lib/python3.8/site-packages/aiohttp/client.py", line 779, in _ws_connect
    resp = await self.request(
  File "/home/itjeong/.local/lib/python3.8/site-packages/aiohttp/client.py", line 536, in _request
    conn = await self._connector.connect(
  File "/home/itjeong/.local/lib/python3.8/site-packages/aiohttp/connector.py", line 540, in connect
    proto = await self._create_connection(req, traces, timeout)
  File "/home/itjeong/.local/lib/python3.8/site-packages/aiohttp/connector.py", line 901, in _create_connection
    _, proto = await self._create_direct_connection(req, traces, timeout)
  File "/home/itjeong/.local/lib/python3.8/site-packages/aiohttp/connector.py", line 1166, in _create_direct_connection
    raise ClientConnectorError(req.connection_key, exc) from exc
aiohttp.client_exceptions.ClientConnectorError: Cannot connect to host gateway-us-east1-c.discord.gg:443 ssl:default [Temporary failure in name resolution]
[2023-03-13 11:42:44] [ERROR   ] discord.client: Attempting a reconnect in 359.67s
Traceback (most recent call last):
  File "/home/itjeong/.local/lib/python3.8/site-packages/aiohttp/connector.py", line 1152, in _create_direct_connection
    hosts = await asyncio.shield(host_resolved)
  File "/home/itjeong/.local/lib/python3.8/site-packages/aiohttp/connector.py", line 874, in _resolve_host
    addrs = await self._resolver.resolve(host, port, family=self._family)
  File "/home/itjeong/.local/lib/python3.8/site-packages/aiohttp/resolver.py", line 33, in resolve
    infos = await self._loop.getaddrinfo(
  File "/usr/lib/python3.8/asyncio/base_events.py", line 825, in getaddrinfo
    return await self.run_in_executor(
  File "/usr/lib/python3.8/concurrent/futures/thread.py", line 57, in run
    result = self.fn(*self.args, **self.kwargs)
  File "/usr/lib/python3.8/socket.py", line 918, in getaddrinfo
    for res in _socket.getaddrinfo(host, port, family, type, proto, flags):
socket.gaierror: [Errno -3] Temporary failure in name resolution

The above exception was the direct cause of the following exception:

Traceback (most recent call last):
  File "/home/itjeong/.local/lib/python3.8/site-packages/discord/client.py", line 656, in connect
    self.ws = await asyncio.wait_for(coro, timeout=60.0)
  File "/usr/lib/python3.8/asyncio/tasks.py", line 494, in wait_for
    return fut.result()
  File "/home/itjeong/.local/lib/python3.8/site-packages/discord/gateway.py", line 372, in from_client
    socket = await client.http.ws_connect(str(url))
  File "/home/itjeong/.local/lib/python3.8/site-packages/discord/http.py", line 536, in ws_connect
    return await self.__session.ws_connect(url, **kwargs)
  File "/home/itjeong/.local/lib/python3.8/site-packages/aiohttp/client.py", line 779, in _ws_connect
    resp = await self.request(
  File "/home/itjeong/.local/lib/python3.8/site-packages/aiohttp/client.py", line 536, in _request
    conn = await self._connector.connect(
  File "/home/itjeong/.local/lib/python3.8/site-packages/aiohttp/connector.py", line 540, in connect
    proto = await self._create_connection(req, traces, timeout)
  File "/home/itjeong/.local/lib/python3.8/site-packages/aiohttp/connector.py", line 901, in _create_connection
    _, proto = await self._create_direct_connection(req, traces, timeout)
  File "/home/itjeong/.local/lib/python3.8/site-packages/aiohttp/connector.py", line 1166, in _create_direct_connection
    raise ClientConnectorError(req.connection_key, exc) from exc
aiohttp.client_exceptions.ClientConnectorError: Cannot connect to host gateway-us-east1-c.discord.gg:443 ssl:default [Temporary failure in name resolution]
[2023-03-13 11:48:53] [ERROR   ] discord.client: Attempting a reconnect in 687.16s
Traceback (most recent call last):
  File "/home/itjeong/.local/lib/python3.8/site-packages/aiohttp/connector.py", line 1152, in _create_direct_connection
    hosts = await asyncio.shield(host_resolved)
  File "/home/itjeong/.local/lib/python3.8/site-packages/aiohttp/connector.py", line 874, in _resolve_host
    addrs = await self._resolver.resolve(host, port, family=self._family)
  File "/home/itjeong/.local/lib/python3.8/site-packages/aiohttp/resolver.py", line 33, in resolve
    infos = await self._loop.getaddrinfo(
  File "/usr/lib/python3.8/asyncio/base_events.py", line 825, in getaddrinfo
    return await self.run_in_executor(
  File "/usr/lib/python3.8/concurrent/futures/thread.py", line 57, in run
    result = self.fn(*self.args, **self.kwargs)
  File "/usr/lib/python3.8/socket.py", line 918, in getaddrinfo
    for res in _socket.getaddrinfo(host, port, family, type, proto, flags):
socket.gaierror: [Errno -3] Temporary failure in name resolution

The above exception was the direct cause of the following exception:

Traceback (most recent call last):
  File "/home/itjeong/.local/lib/python3.8/site-packages/discord/client.py", line 656, in connect
    self.ws = await asyncio.wait_for(coro, timeout=60.0)
  File "/usr/lib/python3.8/asyncio/tasks.py", line 494, in wait_for
    return fut.result()
  File "/home/itjeong/.local/lib/python3.8/site-packages/discord/gateway.py", line 372, in from_client
    socket = await client.http.ws_connect(str(url))
  File "/home/itjeong/.local/lib/python3.8/site-packages/discord/http.py", line 536, in ws_connect
    return await self.__session.ws_connect(url, **kwargs)
  File "/home/itjeong/.local/lib/python3.8/site-packages/aiohttp/client.py", line 779, in _ws_connect
    resp = await self.request(
  File "/home/itjeong/.local/lib/python3.8/site-packages/aiohttp/client.py", line 536, in _request
    conn = await self._connector.connect(
  File "/home/itjeong/.local/lib/python3.8/site-packages/aiohttp/connector.py", line 540, in connect
    proto = await self._create_connection(req, traces, timeout)
  File "/home/itjeong/.local/lib/python3.8/site-packages/aiohttp/connector.py", line 901, in _create_connection
    _, proto = await self._create_direct_connection(req, traces, timeout)
  File "/home/itjeong/.local/lib/python3.8/site-packages/aiohttp/connector.py", line 1166, in _create_direct_connection
    raise ClientConnectorError(req.connection_key, exc) from exc
aiohttp.client_exceptions.ClientConnectorError: Cannot connect to host gateway-us-east1-c.discord.gg:443 ssl:default [Temporary failure in name resolution]
[2023-03-13 12:00:31] [ERROR   ] discord.client: Attempting a reconnect in 6.65s
Traceback (most recent call last):
  File "/home/itjeong/.local/lib/python3.8/site-packages/aiohttp/connector.py", line 1152, in _create_direct_connection
    hosts = await asyncio.shield(host_resolved)
  File "/home/itjeong/.local/lib/python3.8/site-packages/aiohttp/connector.py", line 874, in _resolve_host
    addrs = await self._resolver.resolve(host, port, family=self._family)
  File "/home/itjeong/.local/lib/python3.8/site-packages/aiohttp/resolver.py", line 33, in resolve
    infos = await self._loop.getaddrinfo(
  File "/usr/lib/python3.8/asyncio/base_events.py", line 825, in getaddrinfo
    return await self.run_in_executor(
  File "/usr/lib/python3.8/concurrent/futures/thread.py", line 57, in run
    result = self.fn(*self.args, **self.kwargs)
  File "/usr/lib/python3.8/socket.py", line 918, in getaddrinfo
    for res in _socket.getaddrinfo(host, port, family, type, proto, flags):
socket.gaierror: [Errno -3] Temporary failure in name resolution

The above exception was the direct cause of the following exception:

Traceback (most recent call last):
  File "/home/itjeong/.local/lib/python3.8/site-packages/discord/client.py", line 656, in connect
    self.ws = await asyncio.wait_for(coro, timeout=60.0)
  File "/usr/lib/python3.8/asyncio/tasks.py", line 494, in wait_for
    return fut.result()
  File "/home/itjeong/.local/lib/python3.8/site-packages/discord/gateway.py", line 372, in from_client
    socket = await client.http.ws_connect(str(url))
  File "/home/itjeong/.local/lib/python3.8/site-packages/discord/http.py", line 536, in ws_connect
    return await self.__session.ws_connect(url, **kwargs)
  File "/home/itjeong/.local/lib/python3.8/site-packages/aiohttp/client.py", line 779, in _ws_connect
    resp = await self.request(
  File "/home/itjeong/.local/lib/python3.8/site-packages/aiohttp/client.py", line 536, in _request
    conn = await self._connector.connect(
  File "/home/itjeong/.local/lib/python3.8/site-packages/aiohttp/connector.py", line 540, in connect
    proto = await self._create_connection(req, traces, timeout)
  File "/home/itjeong/.local/lib/python3.8/site-packages/aiohttp/connector.py", line 901, in _create_connection
    _, proto = await self._create_direct_connection(req, traces, timeout)
  File "/home/itjeong/.local/lib/python3.8/site-packages/aiohttp/connector.py", line 1166, in _create_direct_connection
    raise ClientConnectorError(req.connection_key, exc) from exc
aiohttp.client_exceptions.ClientConnectorError: Cannot connect to host gateway-us-east1-c.discord.gg:443 ssl:default [Temporary failure in name resolution]
[2023-03-13 12:00:47] [ERROR   ] discord.client: Attempting a reconnect in 774.97s
Traceback (most recent call last):
  File "/home/itjeong/.local/lib/python3.8/site-packages/aiohttp/connector.py", line 1152, in _create_direct_connection
    hosts = await asyncio.shield(host_resolved)
  File "/home/itjeong/.local/lib/python3.8/site-packages/aiohttp/connector.py", line 874, in _resolve_host
    addrs = await self._resolver.resolve(host, port, family=self._family)
  File "/home/itjeong/.local/lib/python3.8/site-packages/aiohttp/resolver.py", line 33, in resolve
    infos = await self._loop.getaddrinfo(
  File "/usr/lib/python3.8/asyncio/base_events.py", line 825, in getaddrinfo
    return await self.run_in_executor(
  File "/usr/lib/python3.8/concurrent/futures/thread.py", line 57, in run
    result = self.fn(*self.args, **self.kwargs)
  File "/usr/lib/python3.8/socket.py", line 918, in getaddrinfo
    for res in _socket.getaddrinfo(host, port, family, type, proto, flags):
socket.gaierror: [Errno -3] Temporary failure in name resolution

The above exception was the direct cause of the following exception:

Traceback (most recent call last):
  File "/home/itjeong/.local/lib/python3.8/site-packages/discord/client.py", line 656, in connect
    self.ws = await asyncio.wait_for(coro, timeout=60.0)
  File "/usr/lib/python3.8/asyncio/tasks.py", line 494, in wait_for
    return fut.result()
  File "/home/itjeong/.local/lib/python3.8/site-packages/discord/gateway.py", line 372, in from_client
    socket = await client.http.ws_connect(str(url))
  File "/home/itjeong/.local/lib/python3.8/site-packages/discord/http.py", line 536, in ws_connect
    return await self.__session.ws_connect(url, **kwargs)
  File "/home/itjeong/.local/lib/python3.8/site-packages/aiohttp/client.py", line 779, in _ws_connect
    resp = await self.request(
  File "/home/itjeong/.local/lib/python3.8/site-packages/aiohttp/client.py", line 536, in _request
    conn = await self._connector.connect(
  File "/home/itjeong/.local/lib/python3.8/site-packages/aiohttp/connector.py", line 540, in connect
    proto = await self._create_connection(req, traces, timeout)
  File "/home/itjeong/.local/lib/python3.8/site-packages/aiohttp/connector.py", line 901, in _create_connection
    _, proto = await self._create_direct_connection(req, traces, timeout)
  File "/home/itjeong/.local/lib/python3.8/site-packages/aiohttp/connector.py", line 1166, in _create_direct_connection
    raise ClientConnectorError(req.connection_key, exc) from exc
aiohttp.client_exceptions.ClientConnectorError: Cannot connect to host gateway-us-east1-c.discord.gg:443 ssl:default [Temporary failure in name resolution]
[2023-03-13 12:13:52] [ERROR   ] discord.client: Attempting a reconnect in 777.08s
Traceback (most recent call last):
  File "/home/itjeong/.local/lib/python3.8/site-packages/aiohttp/connector.py", line 1152, in _create_direct_connection
    hosts = await asyncio.shield(host_resolved)
  File "/home/itjeong/.local/lib/python3.8/site-packages/aiohttp/connector.py", line 874, in _resolve_host
    addrs = await self._resolver.resolve(host, port, family=self._family)
  File "/home/itjeong/.local/lib/python3.8/site-packages/aiohttp/resolver.py", line 33, in resolve
    infos = await self._loop.getaddrinfo(
  File "/usr/lib/python3.8/asyncio/base_events.py", line 825, in getaddrinfo
    return await self.run_in_executor(
  File "/usr/lib/python3.8/concurrent/futures/thread.py", line 57, in run
    result = self.fn(*self.args, **self.kwargs)
  File "/usr/lib/python3.8/socket.py", line 918, in getaddrinfo
    for res in _socket.getaddrinfo(host, port, family, type, proto, flags):
socket.gaierror: [Errno -3] Temporary failure in name resolution

The above exception was the direct cause of the following exception:

Traceback (most recent call last):
  File "/home/itjeong/.local/lib/python3.8/site-packages/discord/client.py", line 656, in connect
    self.ws = await asyncio.wait_for(coro, timeout=60.0)
  File "/usr/lib/python3.8/asyncio/tasks.py", line 494, in wait_for
    return fut.result()
  File "/home/itjeong/.local/lib/python3.8/site-packages/discord/gateway.py", line 372, in from_client
    socket = await client.http.ws_connect(str(url))
  File "/home/itjeong/.local/lib/python3.8/site-packages/discord/http.py", line 536, in ws_connect
    return await self.__session.ws_connect(url, **kwargs)
  File "/home/itjeong/.local/lib/python3.8/site-packages/aiohttp/client.py", line 779, in _ws_connect
    resp = await self.request(
  File "/home/itjeong/.local/lib/python3.8/site-packages/aiohttp/client.py", line 536, in _request
    conn = await self._connector.connect(
  File "/home/itjeong/.local/lib/python3.8/site-packages/aiohttp/connector.py", line 540, in connect
    proto = await self._create_connection(req, traces, timeout)
  File "/home/itjeong/.local/lib/python3.8/site-packages/aiohttp/connector.py", line 901, in _create_connection
    _, proto = await self._create_direct_connection(req, traces, timeout)
  File "/home/itjeong/.local/lib/python3.8/site-packages/aiohttp/connector.py", line 1166, in _create_direct_connection
    raise ClientConnectorError(req.connection_key, exc) from exc
aiohttp.client_exceptions.ClientConnectorError: Cannot connect to host gateway-us-east1-c.discord.gg:443 ssl:default [Temporary failure in name resolution]
[2023-03-13 12:27:00] [ERROR   ] discord.client: Attempting a reconnect in 298.89s
Traceback (most recent call last):
  File "/home/itjeong/.local/lib/python3.8/site-packages/aiohttp/connector.py", line 1152, in _create_direct_connection
    hosts = await asyncio.shield(host_resolved)
  File "/home/itjeong/.local/lib/python3.8/site-packages/aiohttp/connector.py", line 874, in _resolve_host
    addrs = await self._resolver.resolve(host, port, family=self._family)
  File "/home/itjeong/.local/lib/python3.8/site-packages/aiohttp/resolver.py", line 33, in resolve
    infos = await self._loop.getaddrinfo(
  File "/usr/lib/python3.8/asyncio/base_events.py", line 825, in getaddrinfo
    return await self.run_in_executor(
  File "/usr/lib/python3.8/concurrent/futures/thread.py", line 57, in run
    result = self.fn(*self.args, **self.kwargs)
  File "/usr/lib/python3.8/socket.py", line 918, in getaddrinfo
    for res in _socket.getaddrinfo(host, port, family, type, proto, flags):
socket.gaierror: [Errno -3] Temporary failure in name resolution

The above exception was the direct cause of the following exception:

Traceback (most recent call last):
  File "/home/itjeong/.local/lib/python3.8/site-packages/discord/client.py", line 656, in connect
    self.ws = await asyncio.wait_for(coro, timeout=60.0)
  File "/usr/lib/python3.8/asyncio/tasks.py", line 494, in wait_for
    return fut.result()
  File "/home/itjeong/.local/lib/python3.8/site-packages/discord/gateway.py", line 372, in from_client
    socket = await client.http.ws_connect(str(url))
  File "/home/itjeong/.local/lib/python3.8/site-packages/discord/http.py", line 536, in ws_connect
    return await self.__session.ws_connect(url, **kwargs)
  File "/home/itjeong/.local/lib/python3.8/site-packages/aiohttp/client.py", line 779, in _ws_connect
    resp = await self.request(
  File "/home/itjeong/.local/lib/python3.8/site-packages/aiohttp/client.py", line 536, in _request
    conn = await self._connector.connect(
  File "/home/itjeong/.local/lib/python3.8/site-packages/aiohttp/connector.py", line 540, in connect
    proto = await self._create_connection(req, traces, timeout)
  File "/home/itjeong/.local/lib/python3.8/site-packages/aiohttp/connector.py", line 901, in _create_connection
    _, proto = await self._create_direct_connection(req, traces, timeout)
  File "/home/itjeong/.local/lib/python3.8/site-packages/aiohttp/connector.py", line 1166, in _create_direct_connection
    raise ClientConnectorError(req.connection_key, exc) from exc
aiohttp.client_exceptions.ClientConnectorError: Cannot connect to host gateway-us-east1-c.discord.gg:443 ssl:default [Temporary failure in name resolution]
[2023-03-13 12:32:09] [ERROR   ] discord.client: Attempting a reconnect in 316.44s
Traceback (most recent call last):
  File "/home/itjeong/.local/lib/python3.8/site-packages/aiohttp/connector.py", line 1152, in _create_direct_connection
    hosts = await asyncio.shield(host_resolved)
  File "/home/itjeong/.local/lib/python3.8/site-packages/aiohttp/connector.py", line 874, in _resolve_host
    addrs = await self._resolver.resolve(host, port, family=self._family)
  File "/home/itjeong/.local/lib/python3.8/site-packages/aiohttp/resolver.py", line 33, in resolve
    infos = await self._loop.getaddrinfo(
  File "/usr/lib/python3.8/asyncio/base_events.py", line 825, in getaddrinfo
    return await self.run_in_executor(
  File "/usr/lib/python3.8/concurrent/futures/thread.py", line 57, in run
    result = self.fn(*self.args, **self.kwargs)
  File "/usr/lib/python3.8/socket.py", line 918, in getaddrinfo
    for res in _socket.getaddrinfo(host, port, family, type, proto, flags):
socket.gaierror: [Errno -3] Temporary failure in name resolution

The above exception was the direct cause of the following exception:

Traceback (most recent call last):
  File "/home/itjeong/.local/lib/python3.8/site-packages/discord/client.py", line 656, in connect
    self.ws = await asyncio.wait_for(coro, timeout=60.0)
  File "/usr/lib/python3.8/asyncio/tasks.py", line 494, in wait_for
    return fut.result()
  File "/home/itjeong/.local/lib/python3.8/site-packages/discord/gateway.py", line 372, in from_client
    socket = await client.http.ws_connect(str(url))
  File "/home/itjeong/.local/lib/python3.8/site-packages/discord/http.py", line 536, in ws_connect
    return await self.__session.ws_connect(url, **kwargs)
  File "/home/itjeong/.local/lib/python3.8/site-packages/aiohttp/client.py", line 779, in _ws_connect
    resp = await self.request(
  File "/home/itjeong/.local/lib/python3.8/site-packages/aiohttp/client.py", line 536, in _request
    conn = await self._connector.connect(
  File "/home/itjeong/.local/lib/python3.8/site-packages/aiohttp/connector.py", line 540, in connect
    proto = await self._create_connection(req, traces, timeout)
  File "/home/itjeong/.local/lib/python3.8/site-packages/aiohttp/connector.py", line 901, in _create_connection
    _, proto = await self._create_direct_connection(req, traces, timeout)
  File "/home/itjeong/.local/lib/python3.8/site-packages/aiohttp/connector.py", line 1166, in _create_direct_connection
    raise ClientConnectorError(req.connection_key, exc) from exc
aiohttp.client_exceptions.ClientConnectorError: Cannot connect to host gateway-us-east1-c.discord.gg:443 ssl:default [Temporary failure in name resolution]
[2023-03-13 12:37:35] [ERROR   ] discord.client: Attempting a reconnect in 651.57s
Traceback (most recent call last):
  File "/home/itjeong/.local/lib/python3.8/site-packages/aiohttp/connector.py", line 1152, in _create_direct_connection
    hosts = await asyncio.shield(host_resolved)
  File "/home/itjeong/.local/lib/python3.8/site-packages/aiohttp/connector.py", line 874, in _resolve_host
    addrs = await self._resolver.resolve(host, port, family=self._family)
  File "/home/itjeong/.local/lib/python3.8/site-packages/aiohttp/resolver.py", line 33, in resolve
    infos = await self._loop.getaddrinfo(
  File "/usr/lib/python3.8/asyncio/base_events.py", line 825, in getaddrinfo
    return await self.run_in_executor(
  File "/usr/lib/python3.8/concurrent/futures/thread.py", line 57, in run
    result = self.fn(*self.args, **self.kwargs)
  File "/usr/lib/python3.8/socket.py", line 918, in getaddrinfo
    for res in _socket.getaddrinfo(host, port, family, type, proto, flags):
socket.gaierror: [Errno -3] Temporary failure in name resolution

The above exception was the direct cause of the following exception:

Traceback (most recent call last):
  File "/home/itjeong/.local/lib/python3.8/site-packages/discord/client.py", line 656, in connect
    self.ws = await asyncio.wait_for(coro, timeout=60.0)
  File "/usr/lib/python3.8/asyncio/tasks.py", line 494, in wait_for
    return fut.result()
  File "/home/itjeong/.local/lib/python3.8/site-packages/discord/gateway.py", line 372, in from_client
    socket = await client.http.ws_connect(str(url))
  File "/home/itjeong/.local/lib/python3.8/site-packages/discord/http.py", line 536, in ws_connect
    return await self.__session.ws_connect(url, **kwargs)
  File "/home/itjeong/.local/lib/python3.8/site-packages/aiohttp/client.py", line 779, in _ws_connect
    resp = await self.request(
  File "/home/itjeong/.local/lib/python3.8/site-packages/aiohttp/client.py", line 536, in _request
    conn = await self._connector.connect(
  File "/home/itjeong/.local/lib/python3.8/site-packages/aiohttp/connector.py", line 540, in connect
    proto = await self._create_connection(req, traces, timeout)
  File "/home/itjeong/.local/lib/python3.8/site-packages/aiohttp/connector.py", line 901, in _create_connection
    _, proto = await self._create_direct_connection(req, traces, timeout)
  File "/home/itjeong/.local/lib/python3.8/site-packages/aiohttp/connector.py", line 1166, in _create_direct_connection
    raise ClientConnectorError(req.connection_key, exc) from exc
aiohttp.client_exceptions.ClientConnectorError: Cannot connect to host gateway-us-east1-c.discord.gg:443 ssl:default [Temporary failure in name resolution]
[2023-03-13 12:48:37] [ERROR   ] discord.client: Attempting a reconnect in 49.30s
Traceback (most recent call last):
  File "/home/itjeong/.local/lib/python3.8/site-packages/aiohttp/connector.py", line 1152, in _create_direct_connection
    hosts = await asyncio.shield(host_resolved)
  File "/home/itjeong/.local/lib/python3.8/site-packages/aiohttp/connector.py", line 874, in _resolve_host
    addrs = await self._resolver.resolve(host, port, family=self._family)
  File "/home/itjeong/.local/lib/python3.8/site-packages/aiohttp/resolver.py", line 33, in resolve
    infos = await self._loop.getaddrinfo(
  File "/usr/lib/python3.8/asyncio/base_events.py", line 825, in getaddrinfo
    return await self.run_in_executor(
  File "/usr/lib/python3.8/concurrent/futures/thread.py", line 57, in run
    result = self.fn(*self.args, **self.kwargs)
  File "/usr/lib/python3.8/socket.py", line 918, in getaddrinfo
    for res in _socket.getaddrinfo(host, port, family, type, proto, flags):
socket.gaierror: [Errno -3] Temporary failure in name resolution

The above exception was the direct cause of the following exception:

Traceback (most recent call last):
  File "/home/itjeong/.local/lib/python3.8/site-packages/discord/client.py", line 656, in connect
    self.ws = await asyncio.wait_for(coro, timeout=60.0)
  File "/usr/lib/python3.8/asyncio/tasks.py", line 494, in wait_for
    return fut.result()
  File "/home/itjeong/.local/lib/python3.8/site-packages/discord/gateway.py", line 372, in from_client
    socket = await client.http.ws_connect(str(url))
  File "/home/itjeong/.local/lib/python3.8/site-packages/discord/http.py", line 536, in ws_connect
    return await self.__session.ws_connect(url, **kwargs)
  File "/home/itjeong/.local/lib/python3.8/site-packages/aiohttp/client.py", line 779, in _ws_connect
    resp = await self.request(
  File "/home/itjeong/.local/lib/python3.8/site-packages/aiohttp/client.py", line 536, in _request
    conn = await self._connector.connect(
  File "/home/itjeong/.local/lib/python3.8/site-packages/aiohttp/connector.py", line 540, in connect
    proto = await self._create_connection(req, traces, timeout)
  File "/home/itjeong/.local/lib/python3.8/site-packages/aiohttp/connector.py", line 901, in _create_connection
    _, proto = await self._create_direct_connection(req, traces, timeout)
  File "/home/itjeong/.local/lib/python3.8/site-packages/aiohttp/connector.py", line 1166, in _create_direct_connection
    raise ClientConnectorError(req.connection_key, exc) from exc
aiohttp.client_exceptions.ClientConnectorError: Cannot connect to host gateway-us-east1-c.discord.gg:443 ssl:default [Temporary failure in name resolution]
[2023-03-13 12:49:36] [ERROR   ] discord.client: Attempting a reconnect in 311.62s
Traceback (most recent call last):
  File "/home/itjeong/.local/lib/python3.8/site-packages/aiohttp/connector.py", line 1152, in _create_direct_connection
    hosts = await asyncio.shield(host_resolved)
  File "/home/itjeong/.local/lib/python3.8/site-packages/aiohttp/connector.py", line 874, in _resolve_host
    addrs = await self._resolver.resolve(host, port, family=self._family)
  File "/home/itjeong/.local/lib/python3.8/site-packages/aiohttp/resolver.py", line 33, in resolve
    infos = await self._loop.getaddrinfo(
  File "/usr/lib/python3.8/asyncio/base_events.py", line 825, in getaddrinfo
    return await self.run_in_executor(
  File "/usr/lib/python3.8/concurrent/futures/thread.py", line 57, in run
    result = self.fn(*self.args, **self.kwargs)
  File "/usr/lib/python3.8/socket.py", line 918, in getaddrinfo
    for res in _socket.getaddrinfo(host, port, family, type, proto, flags):
socket.gaierror: [Errno -3] Temporary failure in name resolution

The above exception was the direct cause of the following exception:

Traceback (most recent call last):
  File "/home/itjeong/.local/lib/python3.8/site-packages/discord/client.py", line 656, in connect
    self.ws = await asyncio.wait_for(coro, timeout=60.0)
  File "/usr/lib/python3.8/asyncio/tasks.py", line 494, in wait_for
    return fut.result()
  File "/home/itjeong/.local/lib/python3.8/site-packages/discord/gateway.py", line 372, in from_client
    socket = await client.http.ws_connect(str(url))
  File "/home/itjeong/.local/lib/python3.8/site-packages/discord/http.py", line 536, in ws_connect
    return await self.__session.ws_connect(url, **kwargs)
  File "/home/itjeong/.local/lib/python3.8/site-packages/aiohttp/client.py", line 779, in _ws_connect
    resp = await self.request(
  File "/home/itjeong/.local/lib/python3.8/site-packages/aiohttp/client.py", line 536, in _request
    conn = await self._connector.connect(
  File "/home/itjeong/.local/lib/python3.8/site-packages/aiohttp/connector.py", line 540, in connect
    proto = await self._create_connection(req, traces, timeout)
  File "/home/itjeong/.local/lib/python3.8/site-packages/aiohttp/connector.py", line 901, in _create_connection
    _, proto = await self._create_direct_connection(req, traces, timeout)
  File "/home/itjeong/.local/lib/python3.8/site-packages/aiohttp/connector.py", line 1166, in _create_direct_connection
    raise ClientConnectorError(req.connection_key, exc) from exc
aiohttp.client_exceptions.ClientConnectorError: Cannot connect to host gateway-us-east1-c.discord.gg:443 ssl:default [Temporary failure in name resolution]
[2023-03-13 12:54:58] [ERROR   ] discord.client: Attempting a reconnect in 76.40s
Traceback (most recent call last):
  File "/home/itjeong/.local/lib/python3.8/site-packages/aiohttp/connector.py", line 1152, in _create_direct_connection
    hosts = await asyncio.shield(host_resolved)
  File "/home/itjeong/.local/lib/python3.8/site-packages/aiohttp/connector.py", line 874, in _resolve_host
    addrs = await self._resolver.resolve(host, port, family=self._family)
  File "/home/itjeong/.local/lib/python3.8/site-packages/aiohttp/resolver.py", line 33, in resolve
    infos = await self._loop.getaddrinfo(
  File "/usr/lib/python3.8/asyncio/base_events.py", line 825, in getaddrinfo
    return await self.run_in_executor(
  File "/usr/lib/python3.8/concurrent/futures/thread.py", line 57, in run
    result = self.fn(*self.args, **self.kwargs)
  File "/usr/lib/python3.8/socket.py", line 918, in getaddrinfo
    for res in _socket.getaddrinfo(host, port, family, type, proto, flags):
socket.gaierror: [Errno -3] Temporary failure in name resolution

The above exception was the direct cause of the following exception:

Traceback (most recent call last):
  File "/home/itjeong/.local/lib/python3.8/site-packages/discord/client.py", line 656, in connect
    self.ws = await asyncio.wait_for(coro, timeout=60.0)
  File "/usr/lib/python3.8/asyncio/tasks.py", line 494, in wait_for
    return fut.result()
  File "/home/itjeong/.local/lib/python3.8/site-packages/discord/gateway.py", line 372, in from_client
    socket = await client.http.ws_connect(str(url))
  File "/home/itjeong/.local/lib/python3.8/site-packages/discord/http.py", line 536, in ws_connect
    return await self.__session.ws_connect(url, **kwargs)
  File "/home/itjeong/.local/lib/python3.8/site-packages/aiohttp/client.py", line 779, in _ws_connect
    resp = await self.request(
  File "/home/itjeong/.local/lib/python3.8/site-packages/aiohttp/client.py", line 536, in _request
    conn = await self._connector.connect(
  File "/home/itjeong/.local/lib/python3.8/site-packages/aiohttp/connector.py", line 540, in connect
    proto = await self._create_connection(req, traces, timeout)
  File "/home/itjeong/.local/lib/python3.8/site-packages/aiohttp/connector.py", line 901, in _create_connection
    _, proto = await self._create_direct_connection(req, traces, timeout)
  File "/home/itjeong/.local/lib/python3.8/site-packages/aiohttp/connector.py", line 1166, in _create_direct_connection
    raise ClientConnectorError(req.connection_key, exc) from exc
aiohttp.client_exceptions.ClientConnectorError: Cannot connect to host gateway-us-east1-c.discord.gg:443 ssl:default [Temporary failure in name resolution]
[2023-03-13 12:56:24] [ERROR   ] discord.client: Attempting a reconnect in 8.09s
Traceback (most recent call last):
  File "/home/itjeong/.local/lib/python3.8/site-packages/aiohttp/connector.py", line 1152, in _create_direct_connection
    hosts = await asyncio.shield(host_resolved)
  File "/home/itjeong/.local/lib/python3.8/site-packages/aiohttp/connector.py", line 874, in _resolve_host
    addrs = await self._resolver.resolve(host, port, family=self._family)
  File "/home/itjeong/.local/lib/python3.8/site-packages/aiohttp/resolver.py", line 33, in resolve
    infos = await self._loop.getaddrinfo(
  File "/usr/lib/python3.8/asyncio/base_events.py", line 825, in getaddrinfo
    return await self.run_in_executor(
  File "/usr/lib/python3.8/concurrent/futures/thread.py", line 57, in run
    result = self.fn(*self.args, **self.kwargs)
  File "/usr/lib/python3.8/socket.py", line 918, in getaddrinfo
    for res in _socket.getaddrinfo(host, port, family, type, proto, flags):
socket.gaierror: [Errno -3] Temporary failure in name resolution

The above exception was the direct cause of the following exception:

Traceback (most recent call last):
  File "/home/itjeong/.local/lib/python3.8/site-packages/discord/client.py", line 656, in connect
    self.ws = await asyncio.wait_for(coro, timeout=60.0)
  File "/usr/lib/python3.8/asyncio/tasks.py", line 494, in wait_for
    return fut.result()
  File "/home/itjeong/.local/lib/python3.8/site-packages/discord/gateway.py", line 372, in from_client
    socket = await client.http.ws_connect(str(url))
  File "/home/itjeong/.local/lib/python3.8/site-packages/discord/http.py", line 536, in ws_connect
    return await self.__session.ws_connect(url, **kwargs)
  File "/home/itjeong/.local/lib/python3.8/site-packages/aiohttp/client.py", line 779, in _ws_connect
    resp = await self.request(
  File "/home/itjeong/.local/lib/python3.8/site-packages/aiohttp/client.py", line 536, in _request
    conn = await self._connector.connect(
  File "/home/itjeong/.local/lib/python3.8/site-packages/aiohttp/connector.py", line 540, in connect
    proto = await self._create_connection(req, traces, timeout)
  File "/home/itjeong/.local/lib/python3.8/site-packages/aiohttp/connector.py", line 901, in _create_connection
    _, proto = await self._create_direct_connection(req, traces, timeout)
  File "/home/itjeong/.local/lib/python3.8/site-packages/aiohttp/connector.py", line 1166, in _create_direct_connection
    raise ClientConnectorError(req.connection_key, exc) from exc
aiohttp.client_exceptions.ClientConnectorError: Cannot connect to host gateway-us-east1-c.discord.gg:443 ssl:default [Temporary failure in name resolution]
[2023-03-13 12:56:42] [ERROR   ] discord.client: Attempting a reconnect in 902.07s
Traceback (most recent call last):
  File "/home/itjeong/.local/lib/python3.8/site-packages/aiohttp/connector.py", line 1152, in _create_direct_connection
    hosts = await asyncio.shield(host_resolved)
  File "/home/itjeong/.local/lib/python3.8/site-packages/aiohttp/connector.py", line 874, in _resolve_host
    addrs = await self._resolver.resolve(host, port, family=self._family)
  File "/home/itjeong/.local/lib/python3.8/site-packages/aiohttp/resolver.py", line 33, in resolve
    infos = await self._loop.getaddrinfo(
  File "/usr/lib/python3.8/asyncio/base_events.py", line 825, in getaddrinfo
    return await self.run_in_executor(
  File "/usr/lib/python3.8/concurrent/futures/thread.py", line 57, in run
    result = self.fn(*self.args, **self.kwargs)
  File "/usr/lib/python3.8/socket.py", line 918, in getaddrinfo
    for res in _socket.getaddrinfo(host, port, family, type, proto, flags):
socket.gaierror: [Errno -3] Temporary failure in name resolution

The above exception was the direct cause of the following exception:

Traceback (most recent call last):
  File "/home/itjeong/.local/lib/python3.8/site-packages/discord/client.py", line 656, in connect
    self.ws = await asyncio.wait_for(coro, timeout=60.0)
  File "/usr/lib/python3.8/asyncio/tasks.py", line 494, in wait_for
    return fut.result()
  File "/home/itjeong/.local/lib/python3.8/site-packages/discord/gateway.py", line 372, in from_client
    socket = await client.http.ws_connect(str(url))
  File "/home/itjeong/.local/lib/python3.8/site-packages/discord/http.py", line 536, in ws_connect
    return await self.__session.ws_connect(url, **kwargs)
  File "/home/itjeong/.local/lib/python3.8/site-packages/aiohttp/client.py", line 779, in _ws_connect
    resp = await self.request(
  File "/home/itjeong/.local/lib/python3.8/site-packages/aiohttp/client.py", line 536, in _request
    conn = await self._connector.connect(
  File "/home/itjeong/.local/lib/python3.8/site-packages/aiohttp/connector.py", line 540, in connect
    proto = await self._create_connection(req, traces, timeout)
  File "/home/itjeong/.local/lib/python3.8/site-packages/aiohttp/connector.py", line 901, in _create_connection
    _, proto = await self._create_direct_connection(req, traces, timeout)
  File "/home/itjeong/.local/lib/python3.8/site-packages/aiohttp/connector.py", line 1166, in _create_direct_connection
    raise ClientConnectorError(req.connection_key, exc) from exc
aiohttp.client_exceptions.ClientConnectorError: Cannot connect to host gateway-us-east1-c.discord.gg:443 ssl:default [Temporary failure in name resolution]
[2023-03-13 13:11:45] [INFO    ] discord.gateway: Shard ID None session has been invalidated.
[2023-03-13 13:11:51] [INFO    ] discord.gateway: Shard ID None has connected to Gateway (Session ID: 720db18a2e312df04861298378b5c72a).
[2023-03-13 13:44:20] [INFO    ] discord.gateway: Shard ID None has successfully RESUMED session 720db18a2e312df04861298378b5c72a.
[2023-03-13 15:35:10] [INFO    ] discord.gateway: Shard ID None has successfully RESUMED session 720db18a2e312df04861298378b5c72a.
[2023-03-13 23:12:38] [INFO    ] discord.client: logging in using static token
[2023-03-13 23:12:39] [INFO    ] discord.gateway: Shard ID None has connected to Gateway (Session ID: 190785ae75c05fd977f04f1b551ed998).
[2023-03-14 00:53:57] [INFO    ] discord.gateway: Shard ID None has successfully RESUMED session 190785ae75c05fd977f04f1b551ed998.
[2023-03-02 22:00:58] [INFO    ] discord.client: logging in using static token
[2023-03-02 22:00:59] [INFO    ] discord.gateway: Shard ID None has connected to Gateway (Session ID: 2aac8984f1d5f2747daaeddda4c2000e).
[2023-03-14 11:23:27] [INFO    ] discord.client: logging in using static token
[2023-03-14 11:23:28] [INFO    ] discord.gateway: Shard ID None has connected to Gateway (Session ID: c387bb40d51bcba0c7d0e2ee479fd123).
[2023-03-14 14:58:49] [INFO    ] discord.gateway: Shard ID None has successfully RESUMED session c387bb40d51bcba0c7d0e2ee479fd123.
[2023-03-14 15:28:15] [INFO    ] discord.gateway: Shard ID None has successfully RESUMED session c387bb40d51bcba0c7d0e2ee479fd123.
[2023-03-14 17:55:27] [INFO    ] discord.gateway: Shard ID None has successfully RESUMED session c387bb40d51bcba0c7d0e2ee479fd123.
[2023-03-14 21:28:15] [INFO    ] discord.gateway: Shard ID None has successfully RESUMED session c387bb40d51bcba0c7d0e2ee479fd123.
[2023-03-14 22:14:17] [INFO    ] discord.gateway: Shard ID None has successfully RESUMED session c387bb40d51bcba0c7d0e2ee479fd123.
[2023-03-14 23:25:40] [INFO    ] discord.gateway: Shard ID None has successfully RESUMED session c387bb40d51bcba0c7d0e2ee479fd123.
[2023-03-15 01:12:53] [INFO    ] discord.gateway: Shard ID None has successfully RESUMED session c387bb40d51bcba0c7d0e2ee479fd123.
[2023-03-15 03:07:42] [INFO    ] discord.gateway: Shard ID None has successfully RESUMED session c387bb40d51bcba0c7d0e2ee479fd123.
[2023-03-15 03:11:50] [INFO    ] discord.gateway: Shard ID None has successfully RESUMED session c387bb40d51bcba0c7d0e2ee479fd123.
[2023-03-15 06:16:09] [INFO    ] discord.gateway: Shard ID None has successfully RESUMED session c387bb40d51bcba0c7d0e2ee479fd123.
[2023-03-15 09:00:52] [INFO    ] discord.gateway: Shard ID None has successfully RESUMED session c387bb40d51bcba0c7d0e2ee479fd123.
[2023-03-15 11:01:13] [INFO    ] discord.gateway: Shard ID None has successfully RESUMED session c387bb40d51bcba0c7d0e2ee479fd123.
[2023-03-15 14:38:53] [INFO    ] discord.gateway: Shard ID None has successfully RESUMED session c387bb40d51bcba0c7d0e2ee479fd123.
[2023-03-15 16:26:49] [INFO    ] discord.gateway: Shard ID None has successfully RESUMED session c387bb40d51bcba0c7d0e2ee479fd123.
[2023-03-15 19:08:03] [INFO    ] discord.gateway: Shard ID None has successfully RESUMED session c387bb40d51bcba0c7d0e2ee479fd123.
[2023-03-15 21:12:58] [ERROR   ] discord.client: Attempting a reconnect in 1.60s
Traceback (most recent call last):
  File "/home/itjeong/.local/lib/python3.8/site-packages/aiohttp/connector.py", line 1152, in _create_direct_connection
    hosts = await asyncio.shield(host_resolved)
  File "/home/itjeong/.local/lib/python3.8/site-packages/aiohttp/connector.py", line 874, in _resolve_host
    addrs = await self._resolver.resolve(host, port, family=self._family)
  File "/home/itjeong/.local/lib/python3.8/site-packages/aiohttp/resolver.py", line 33, in resolve
    infos = await self._loop.getaddrinfo(
  File "/usr/lib/python3.8/asyncio/base_events.py", line 825, in getaddrinfo
    return await self.run_in_executor(
  File "/usr/lib/python3.8/concurrent/futures/thread.py", line 57, in run
    result = self.fn(*self.args, **self.kwargs)
  File "/usr/lib/python3.8/socket.py", line 918, in getaddrinfo
    for res in _socket.getaddrinfo(host, port, family, type, proto, flags):
socket.gaierror: [Errno -3] Temporary failure in name resolution

The above exception was the direct cause of the following exception:

Traceback (most recent call last):
  File "/home/itjeong/.local/lib/python3.8/site-packages/discord/client.py", line 656, in connect
    self.ws = await asyncio.wait_for(coro, timeout=60.0)
  File "/usr/lib/python3.8/asyncio/tasks.py", line 494, in wait_for
    return fut.result()
  File "/home/itjeong/.local/lib/python3.8/site-packages/discord/gateway.py", line 372, in from_client
    socket = await client.http.ws_connect(str(url))
  File "/home/itjeong/.local/lib/python3.8/site-packages/discord/http.py", line 536, in ws_connect
    return await self.__session.ws_connect(url, **kwargs)
  File "/home/itjeong/.local/lib/python3.8/site-packages/aiohttp/client.py", line 779, in _ws_connect
    resp = await self.request(
  File "/home/itjeong/.local/lib/python3.8/site-packages/aiohttp/client.py", line 536, in _request
    conn = await self._connector.connect(
  File "/home/itjeong/.local/lib/python3.8/site-packages/aiohttp/connector.py", line 540, in connect
    proto = await self._create_connection(req, traces, timeout)
  File "/home/itjeong/.local/lib/python3.8/site-packages/aiohttp/connector.py", line 901, in _create_connection
    _, proto = await self._create_direct_connection(req, traces, timeout)
  File "/home/itjeong/.local/lib/python3.8/site-packages/aiohttp/connector.py", line 1166, in _create_direct_connection
    raise ClientConnectorError(req.connection_key, exc) from exc
aiohttp.client_exceptions.ClientConnectorError: Cannot connect to host gateway-us-east1-d.discord.gg:443 ssl:default [Temporary failure in name resolution]
[2023-03-15 21:13:07] [ERROR   ] discord.client: Attempting a reconnect in 1.96s
Traceback (most recent call last):
  File "/home/itjeong/.local/lib/python3.8/site-packages/aiohttp/connector.py", line 1152, in _create_direct_connection
    hosts = await asyncio.shield(host_resolved)
  File "/home/itjeong/.local/lib/python3.8/site-packages/aiohttp/connector.py", line 874, in _resolve_host
    addrs = await self._resolver.resolve(host, port, family=self._family)
  File "/home/itjeong/.local/lib/python3.8/site-packages/aiohttp/resolver.py", line 33, in resolve
    infos = await self._loop.getaddrinfo(
  File "/usr/lib/python3.8/asyncio/base_events.py", line 825, in getaddrinfo
    return await self.run_in_executor(
  File "/usr/lib/python3.8/concurrent/futures/thread.py", line 57, in run
    result = self.fn(*self.args, **self.kwargs)
  File "/usr/lib/python3.8/socket.py", line 918, in getaddrinfo
    for res in _socket.getaddrinfo(host, port, family, type, proto, flags):
socket.gaierror: [Errno -3] Temporary failure in name resolution

The above exception was the direct cause of the following exception:

Traceback (most recent call last):
  File "/home/itjeong/.local/lib/python3.8/site-packages/discord/client.py", line 656, in connect
    self.ws = await asyncio.wait_for(coro, timeout=60.0)
  File "/usr/lib/python3.8/asyncio/tasks.py", line 494, in wait_for
    return fut.result()
  File "/home/itjeong/.local/lib/python3.8/site-packages/discord/gateway.py", line 372, in from_client
    socket = await client.http.ws_connect(str(url))
  File "/home/itjeong/.local/lib/python3.8/site-packages/discord/http.py", line 536, in ws_connect
    return await self.__session.ws_connect(url, **kwargs)
  File "/home/itjeong/.local/lib/python3.8/site-packages/aiohttp/client.py", line 779, in _ws_connect
    resp = await self.request(
  File "/home/itjeong/.local/lib/python3.8/site-packages/aiohttp/client.py", line 536, in _request
    conn = await self._connector.connect(
  File "/home/itjeong/.local/lib/python3.8/site-packages/aiohttp/connector.py", line 540, in connect
    proto = await self._create_connection(req, traces, timeout)
  File "/home/itjeong/.local/lib/python3.8/site-packages/aiohttp/connector.py", line 901, in _create_connection
    _, proto = await self._create_direct_connection(req, traces, timeout)
  File "/home/itjeong/.local/lib/python3.8/site-packages/aiohttp/connector.py", line 1166, in _create_direct_connection
    raise ClientConnectorError(req.connection_key, exc) from exc
aiohttp.client_exceptions.ClientConnectorError: Cannot connect to host gateway-us-east1-d.discord.gg:443 ssl:default [Temporary failure in name resolution]
[2023-03-15 21:13:19] [ERROR   ] discord.client: Attempting a reconnect in 7.76s
Traceback (most recent call last):
  File "/home/itjeong/.local/lib/python3.8/site-packages/aiohttp/connector.py", line 1152, in _create_direct_connection
    hosts = await asyncio.shield(host_resolved)
  File "/home/itjeong/.local/lib/python3.8/site-packages/aiohttp/connector.py", line 874, in _resolve_host
    addrs = await self._resolver.resolve(host, port, family=self._family)
  File "/home/itjeong/.local/lib/python3.8/site-packages/aiohttp/resolver.py", line 33, in resolve
    infos = await self._loop.getaddrinfo(
  File "/usr/lib/python3.8/asyncio/base_events.py", line 825, in getaddrinfo
    return await self.run_in_executor(
  File "/usr/lib/python3.8/concurrent/futures/thread.py", line 57, in run
    result = self.fn(*self.args, **self.kwargs)
  File "/usr/lib/python3.8/socket.py", line 918, in getaddrinfo
    for res in _socket.getaddrinfo(host, port, family, type, proto, flags):
socket.gaierror: [Errno -3] Temporary failure in name resolution

The above exception was the direct cause of the following exception:

Traceback (most recent call last):
  File "/home/itjeong/.local/lib/python3.8/site-packages/discord/client.py", line 656, in connect
    self.ws = await asyncio.wait_for(coro, timeout=60.0)
  File "/usr/lib/python3.8/asyncio/tasks.py", line 494, in wait_for
    return fut.result()
  File "/home/itjeong/.local/lib/python3.8/site-packages/discord/gateway.py", line 372, in from_client
    socket = await client.http.ws_connect(str(url))
  File "/home/itjeong/.local/lib/python3.8/site-packages/discord/http.py", line 536, in ws_connect
    return await self.__session.ws_connect(url, **kwargs)
  File "/home/itjeong/.local/lib/python3.8/site-packages/aiohttp/client.py", line 779, in _ws_connect
    resp = await self.request(
  File "/home/itjeong/.local/lib/python3.8/site-packages/aiohttp/client.py", line 536, in _request
    conn = await self._connector.connect(
  File "/home/itjeong/.local/lib/python3.8/site-packages/aiohttp/connector.py", line 540, in connect
    proto = await self._create_connection(req, traces, timeout)
  File "/home/itjeong/.local/lib/python3.8/site-packages/aiohttp/connector.py", line 901, in _create_connection
    _, proto = await self._create_direct_connection(req, traces, timeout)
  File "/home/itjeong/.local/lib/python3.8/site-packages/aiohttp/connector.py", line 1166, in _create_direct_connection
    raise ClientConnectorError(req.connection_key, exc) from exc
aiohttp.client_exceptions.ClientConnectorError: Cannot connect to host gateway-us-east1-d.discord.gg:443 ssl:default [Temporary failure in name resolution]
[2023-03-15 21:13:37] [ERROR   ] discord.client: Attempting a reconnect in 3.16s
Traceback (most recent call last):
  File "/home/itjeong/.local/lib/python3.8/site-packages/aiohttp/connector.py", line 1152, in _create_direct_connection
    hosts = await asyncio.shield(host_resolved)
  File "/home/itjeong/.local/lib/python3.8/site-packages/aiohttp/connector.py", line 874, in _resolve_host
    addrs = await self._resolver.resolve(host, port, family=self._family)
  File "/home/itjeong/.local/lib/python3.8/site-packages/aiohttp/resolver.py", line 33, in resolve
    infos = await self._loop.getaddrinfo(
  File "/usr/lib/python3.8/asyncio/base_events.py", line 825, in getaddrinfo
    return await self.run_in_executor(
  File "/usr/lib/python3.8/concurrent/futures/thread.py", line 57, in run
    result = self.fn(*self.args, **self.kwargs)
  File "/usr/lib/python3.8/socket.py", line 918, in getaddrinfo
    for res in _socket.getaddrinfo(host, port, family, type, proto, flags):
socket.gaierror: [Errno -3] Temporary failure in name resolution

The above exception was the direct cause of the following exception:

Traceback (most recent call last):
  File "/home/itjeong/.local/lib/python3.8/site-packages/discord/client.py", line 656, in connect
    self.ws = await asyncio.wait_for(coro, timeout=60.0)
  File "/usr/lib/python3.8/asyncio/tasks.py", line 494, in wait_for
    return fut.result()
  File "/home/itjeong/.local/lib/python3.8/site-packages/discord/gateway.py", line 372, in from_client
    socket = await client.http.ws_connect(str(url))
  File "/home/itjeong/.local/lib/python3.8/site-packages/discord/http.py", line 536, in ws_connect
    return await self.__session.ws_connect(url, **kwargs)
  File "/home/itjeong/.local/lib/python3.8/site-packages/aiohttp/client.py", line 779, in _ws_connect
    resp = await self.request(
  File "/home/itjeong/.local/lib/python3.8/site-packages/aiohttp/client.py", line 536, in _request
    conn = await self._connector.connect(
  File "/home/itjeong/.local/lib/python3.8/site-packages/aiohttp/connector.py", line 540, in connect
    proto = await self._create_connection(req, traces, timeout)
  File "/home/itjeong/.local/lib/python3.8/site-packages/aiohttp/connector.py", line 901, in _create_connection
    _, proto = await self._create_direct_connection(req, traces, timeout)
  File "/home/itjeong/.local/lib/python3.8/site-packages/aiohttp/connector.py", line 1166, in _create_direct_connection
    raise ClientConnectorError(req.connection_key, exc) from exc
aiohttp.client_exceptions.ClientConnectorError: Cannot connect to host gateway-us-east1-d.discord.gg:443 ssl:default [Temporary failure in name resolution]
[2023-03-15 21:13:48] [ERROR   ] discord.client: Attempting a reconnect in 2.74s
Traceback (most recent call last):
  File "/home/itjeong/.local/lib/python3.8/site-packages/aiohttp/connector.py", line 1152, in _create_direct_connection
    hosts = await asyncio.shield(host_resolved)
  File "/home/itjeong/.local/lib/python3.8/site-packages/aiohttp/connector.py", line 874, in _resolve_host
    addrs = await self._resolver.resolve(host, port, family=self._family)
  File "/home/itjeong/.local/lib/python3.8/site-packages/aiohttp/resolver.py", line 33, in resolve
    infos = await self._loop.getaddrinfo(
  File "/usr/lib/python3.8/asyncio/base_events.py", line 825, in getaddrinfo
    return await self.run_in_executor(
  File "/usr/lib/python3.8/concurrent/futures/thread.py", line 57, in run
    result = self.fn(*self.args, **self.kwargs)
  File "/usr/lib/python3.8/socket.py", line 918, in getaddrinfo
    for res in _socket.getaddrinfo(host, port, family, type, proto, flags):
socket.gaierror: [Errno -3] Temporary failure in name resolution

The above exception was the direct cause of the following exception:

Traceback (most recent call last):
  File "/home/itjeong/.local/lib/python3.8/site-packages/discord/client.py", line 656, in connect
    self.ws = await asyncio.wait_for(coro, timeout=60.0)
  File "/usr/lib/python3.8/asyncio/tasks.py", line 494, in wait_for
    return fut.result()
  File "/home/itjeong/.local/lib/python3.8/site-packages/discord/gateway.py", line 372, in from_client
    socket = await client.http.ws_connect(str(url))
  File "/home/itjeong/.local/lib/python3.8/site-packages/discord/http.py", line 536, in ws_connect
    return await self.__session.ws_connect(url, **kwargs)
  File "/home/itjeong/.local/lib/python3.8/site-packages/aiohttp/client.py", line 779, in _ws_connect
    resp = await self.request(
  File "/home/itjeong/.local/lib/python3.8/site-packages/aiohttp/client.py", line 536, in _request
    conn = await self._connector.connect(
  File "/home/itjeong/.local/lib/python3.8/site-packages/aiohttp/connector.py", line 540, in connect
    proto = await self._create_connection(req, traces, timeout)
  File "/home/itjeong/.local/lib/python3.8/site-packages/aiohttp/connector.py", line 901, in _create_connection
    _, proto = await self._create_direct_connection(req, traces, timeout)
  File "/home/itjeong/.local/lib/python3.8/site-packages/aiohttp/connector.py", line 1166, in _create_direct_connection
    raise ClientConnectorError(req.connection_key, exc) from exc
aiohttp.client_exceptions.ClientConnectorError: Cannot connect to host gateway-us-east1-d.discord.gg:443 ssl:default [Temporary failure in name resolution]
[2023-03-15 21:14:01] [ERROR   ] discord.client: Attempting a reconnect in 47.84s
Traceback (most recent call last):
  File "/home/itjeong/.local/lib/python3.8/site-packages/aiohttp/connector.py", line 1152, in _create_direct_connection
    hosts = await asyncio.shield(host_resolved)
  File "/home/itjeong/.local/lib/python3.8/site-packages/aiohttp/connector.py", line 874, in _resolve_host
    addrs = await self._resolver.resolve(host, port, family=self._family)
  File "/home/itjeong/.local/lib/python3.8/site-packages/aiohttp/resolver.py", line 33, in resolve
    infos = await self._loop.getaddrinfo(
  File "/usr/lib/python3.8/asyncio/base_events.py", line 825, in getaddrinfo
    return await self.run_in_executor(
  File "/usr/lib/python3.8/concurrent/futures/thread.py", line 57, in run
    result = self.fn(*self.args, **self.kwargs)
  File "/usr/lib/python3.8/socket.py", line 918, in getaddrinfo
    for res in _socket.getaddrinfo(host, port, family, type, proto, flags):
socket.gaierror: [Errno -3] Temporary failure in name resolution

The above exception was the direct cause of the following exception:

Traceback (most recent call last):
  File "/home/itjeong/.local/lib/python3.8/site-packages/discord/client.py", line 656, in connect
    self.ws = await asyncio.wait_for(coro, timeout=60.0)
  File "/usr/lib/python3.8/asyncio/tasks.py", line 494, in wait_for
    return fut.result()
  File "/home/itjeong/.local/lib/python3.8/site-packages/discord/gateway.py", line 372, in from_client
    socket = await client.http.ws_connect(str(url))
  File "/home/itjeong/.local/lib/python3.8/site-packages/discord/http.py", line 536, in ws_connect
    return await self.__session.ws_connect(url, **kwargs)
  File "/home/itjeong/.local/lib/python3.8/site-packages/aiohttp/client.py", line 779, in _ws_connect
    resp = await self.request(
  File "/home/itjeong/.local/lib/python3.8/site-packages/aiohttp/client.py", line 536, in _request
    conn = await self._connector.connect(
  File "/home/itjeong/.local/lib/python3.8/site-packages/aiohttp/connector.py", line 540, in connect
    proto = await self._create_connection(req, traces, timeout)
  File "/home/itjeong/.local/lib/python3.8/site-packages/aiohttp/connector.py", line 901, in _create_connection
    _, proto = await self._create_direct_connection(req, traces, timeout)
  File "/home/itjeong/.local/lib/python3.8/site-packages/aiohttp/connector.py", line 1166, in _create_direct_connection
    raise ClientConnectorError(req.connection_key, exc) from exc
aiohttp.client_exceptions.ClientConnectorError: Cannot connect to host gateway-us-east1-d.discord.gg:443 ssl:default [Temporary failure in name resolution]
[2023-03-15 21:14:57] [ERROR   ] discord.client: Attempting a reconnect in 18.02s
Traceback (most recent call last):
  File "/home/itjeong/.local/lib/python3.8/site-packages/aiohttp/connector.py", line 1152, in _create_direct_connection
    hosts = await asyncio.shield(host_resolved)
  File "/home/itjeong/.local/lib/python3.8/site-packages/aiohttp/connector.py", line 874, in _resolve_host
    addrs = await self._resolver.resolve(host, port, family=self._family)
  File "/home/itjeong/.local/lib/python3.8/site-packages/aiohttp/resolver.py", line 33, in resolve
    infos = await self._loop.getaddrinfo(
  File "/usr/lib/python3.8/asyncio/base_events.py", line 825, in getaddrinfo
    return await self.run_in_executor(
  File "/usr/lib/python3.8/concurrent/futures/thread.py", line 57, in run
    result = self.fn(*self.args, **self.kwargs)
  File "/usr/lib/python3.8/socket.py", line 918, in getaddrinfo
    for res in _socket.getaddrinfo(host, port, family, type, proto, flags):
socket.gaierror: [Errno -3] Temporary failure in name resolution

The above exception was the direct cause of the following exception:

Traceback (most recent call last):
  File "/home/itjeong/.local/lib/python3.8/site-packages/discord/client.py", line 656, in connect
    self.ws = await asyncio.wait_for(coro, timeout=60.0)
  File "/usr/lib/python3.8/asyncio/tasks.py", line 494, in wait_for
    return fut.result()
  File "/home/itjeong/.local/lib/python3.8/site-packages/discord/gateway.py", line 372, in from_client
    socket = await client.http.ws_connect(str(url))
  File "/home/itjeong/.local/lib/python3.8/site-packages/discord/http.py", line 536, in ws_connect
    return await self.__session.ws_connect(url, **kwargs)
  File "/home/itjeong/.local/lib/python3.8/site-packages/aiohttp/client.py", line 779, in _ws_connect
    resp = await self.request(
  File "/home/itjeong/.local/lib/python3.8/site-packages/aiohttp/client.py", line 536, in _request
    conn = await self._connector.connect(
  File "/home/itjeong/.local/lib/python3.8/site-packages/aiohttp/connector.py", line 540, in connect
    proto = await self._create_connection(req, traces, timeout)
  File "/home/itjeong/.local/lib/python3.8/site-packages/aiohttp/connector.py", line 901, in _create_connection
    _, proto = await self._create_direct_connection(req, traces, timeout)
  File "/home/itjeong/.local/lib/python3.8/site-packages/aiohttp/connector.py", line 1166, in _create_direct_connection
    raise ClientConnectorError(req.connection_key, exc) from exc
aiohttp.client_exceptions.ClientConnectorError: Cannot connect to host gateway-us-east1-d.discord.gg:443 ssl:default [Temporary failure in name resolution]
[2023-03-15 21:15:25] [ERROR   ] discord.client: Attempting a reconnect in 120.16s
Traceback (most recent call last):
  File "/home/itjeong/.local/lib/python3.8/site-packages/aiohttp/connector.py", line 1152, in _create_direct_connection
    hosts = await asyncio.shield(host_resolved)
  File "/home/itjeong/.local/lib/python3.8/site-packages/aiohttp/connector.py", line 874, in _resolve_host
    addrs = await self._resolver.resolve(host, port, family=self._family)
  File "/home/itjeong/.local/lib/python3.8/site-packages/aiohttp/resolver.py", line 33, in resolve
    infos = await self._loop.getaddrinfo(
  File "/usr/lib/python3.8/asyncio/base_events.py", line 825, in getaddrinfo
    return await self.run_in_executor(
  File "/usr/lib/python3.8/concurrent/futures/thread.py", line 57, in run
    result = self.fn(*self.args, **self.kwargs)
  File "/usr/lib/python3.8/socket.py", line 918, in getaddrinfo
    for res in _socket.getaddrinfo(host, port, family, type, proto, flags):
socket.gaierror: [Errno -3] Temporary failure in name resolution

The above exception was the direct cause of the following exception:

Traceback (most recent call last):
  File "/home/itjeong/.local/lib/python3.8/site-packages/discord/client.py", line 656, in connect
    self.ws = await asyncio.wait_for(coro, timeout=60.0)
  File "/usr/lib/python3.8/asyncio/tasks.py", line 494, in wait_for
    return fut.result()
  File "/home/itjeong/.local/lib/python3.8/site-packages/discord/gateway.py", line 372, in from_client
    socket = await client.http.ws_connect(str(url))
  File "/home/itjeong/.local/lib/python3.8/site-packages/discord/http.py", line 536, in ws_connect
    return await self.__session.ws_connect(url, **kwargs)
  File "/home/itjeong/.local/lib/python3.8/site-packages/aiohttp/client.py", line 779, in _ws_connect
    resp = await self.request(
  File "/home/itjeong/.local/lib/python3.8/site-packages/aiohttp/client.py", line 536, in _request
    conn = await self._connector.connect(
  File "/home/itjeong/.local/lib/python3.8/site-packages/aiohttp/connector.py", line 540, in connect
    proto = await self._create_connection(req, traces, timeout)
  File "/home/itjeong/.local/lib/python3.8/site-packages/aiohttp/connector.py", line 901, in _create_connection
    _, proto = await self._create_direct_connection(req, traces, timeout)
  File "/home/itjeong/.local/lib/python3.8/site-packages/aiohttp/connector.py", line 1166, in _create_direct_connection
    raise ClientConnectorError(req.connection_key, exc) from exc
aiohttp.client_exceptions.ClientConnectorError: Cannot connect to host gateway-us-east1-d.discord.gg:443 ssl:default [Temporary failure in name resolution]
[2023-03-15 21:17:36] [ERROR   ] discord.client: Attempting a reconnect in 289.51s
Traceback (most recent call last):
  File "/home/itjeong/.local/lib/python3.8/site-packages/aiohttp/connector.py", line 1152, in _create_direct_connection
    hosts = await asyncio.shield(host_resolved)
  File "/home/itjeong/.local/lib/python3.8/site-packages/aiohttp/connector.py", line 874, in _resolve_host
    addrs = await self._resolver.resolve(host, port, family=self._family)
  File "/home/itjeong/.local/lib/python3.8/site-packages/aiohttp/resolver.py", line 33, in resolve
    infos = await self._loop.getaddrinfo(
  File "/usr/lib/python3.8/asyncio/base_events.py", line 825, in getaddrinfo
    return await self.run_in_executor(
  File "/usr/lib/python3.8/concurrent/futures/thread.py", line 57, in run
    result = self.fn(*self.args, **self.kwargs)
  File "/usr/lib/python3.8/socket.py", line 918, in getaddrinfo
    for res in _socket.getaddrinfo(host, port, family, type, proto, flags):
socket.gaierror: [Errno -3] Temporary failure in name resolution

The above exception was the direct cause of the following exception:

Traceback (most recent call last):
  File "/home/itjeong/.local/lib/python3.8/site-packages/discord/client.py", line 656, in connect
    self.ws = await asyncio.wait_for(coro, timeout=60.0)
  File "/usr/lib/python3.8/asyncio/tasks.py", line 494, in wait_for
    return fut.result()
  File "/home/itjeong/.local/lib/python3.8/site-packages/discord/gateway.py", line 372, in from_client
    socket = await client.http.ws_connect(str(url))
  File "/home/itjeong/.local/lib/python3.8/site-packages/discord/http.py", line 536, in ws_connect
    return await self.__session.ws_connect(url, **kwargs)
  File "/home/itjeong/.local/lib/python3.8/site-packages/aiohttp/client.py", line 779, in _ws_connect
    resp = await self.request(
  File "/home/itjeong/.local/lib/python3.8/site-packages/aiohttp/client.py", line 536, in _request
    conn = await self._connector.connect(
  File "/home/itjeong/.local/lib/python3.8/site-packages/aiohttp/connector.py", line 540, in connect
    proto = await self._create_connection(req, traces, timeout)
  File "/home/itjeong/.local/lib/python3.8/site-packages/aiohttp/connector.py", line 901, in _create_connection
    _, proto = await self._create_direct_connection(req, traces, timeout)
  File "/home/itjeong/.local/lib/python3.8/site-packages/aiohttp/connector.py", line 1166, in _create_direct_connection
    raise ClientConnectorError(req.connection_key, exc) from exc
aiohttp.client_exceptions.ClientConnectorError: Cannot connect to host gateway-us-east1-d.discord.gg:443 ssl:default [Temporary failure in name resolution]
[2023-03-15 21:22:35] [ERROR   ] discord.client: Attempting a reconnect in 633.43s
Traceback (most recent call last):
  File "/home/itjeong/.local/lib/python3.8/site-packages/aiohttp/connector.py", line 1152, in _create_direct_connection
    hosts = await asyncio.shield(host_resolved)
  File "/home/itjeong/.local/lib/python3.8/site-packages/aiohttp/connector.py", line 874, in _resolve_host
    addrs = await self._resolver.resolve(host, port, family=self._family)
  File "/home/itjeong/.local/lib/python3.8/site-packages/aiohttp/resolver.py", line 33, in resolve
    infos = await self._loop.getaddrinfo(
  File "/usr/lib/python3.8/asyncio/base_events.py", line 825, in getaddrinfo
    return await self.run_in_executor(
  File "/usr/lib/python3.8/concurrent/futures/thread.py", line 57, in run
    result = self.fn(*self.args, **self.kwargs)
  File "/usr/lib/python3.8/socket.py", line 918, in getaddrinfo
    for res in _socket.getaddrinfo(host, port, family, type, proto, flags):
socket.gaierror: [Errno -3] Temporary failure in name resolution

The above exception was the direct cause of the following exception:

Traceback (most recent call last):
  File "/home/itjeong/.local/lib/python3.8/site-packages/discord/client.py", line 656, in connect
    self.ws = await asyncio.wait_for(coro, timeout=60.0)
  File "/usr/lib/python3.8/asyncio/tasks.py", line 494, in wait_for
    return fut.result()
  File "/home/itjeong/.local/lib/python3.8/site-packages/discord/gateway.py", line 372, in from_client
    socket = await client.http.ws_connect(str(url))
  File "/home/itjeong/.local/lib/python3.8/site-packages/discord/http.py", line 536, in ws_connect
    return await self.__session.ws_connect(url, **kwargs)
  File "/home/itjeong/.local/lib/python3.8/site-packages/aiohttp/client.py", line 779, in _ws_connect
    resp = await self.request(
  File "/home/itjeong/.local/lib/python3.8/site-packages/aiohttp/client.py", line 536, in _request
    conn = await self._connector.connect(
  File "/home/itjeong/.local/lib/python3.8/site-packages/aiohttp/connector.py", line 540, in connect
    proto = await self._create_connection(req, traces, timeout)
  File "/home/itjeong/.local/lib/python3.8/site-packages/aiohttp/connector.py", line 901, in _create_connection
    _, proto = await self._create_direct_connection(req, traces, timeout)
  File "/home/itjeong/.local/lib/python3.8/site-packages/aiohttp/connector.py", line 1166, in _create_direct_connection
    raise ClientConnectorError(req.connection_key, exc) from exc
aiohttp.client_exceptions.ClientConnectorError: Cannot connect to host gateway-us-east1-d.discord.gg:443 ssl:default [Temporary failure in name resolution]
[2023-03-15 21:33:19] [ERROR   ] discord.client: Attempting a reconnect in 130.03s
Traceback (most recent call last):
  File "/home/itjeong/.local/lib/python3.8/site-packages/aiohttp/connector.py", line 1152, in _create_direct_connection
    hosts = await asyncio.shield(host_resolved)
  File "/home/itjeong/.local/lib/python3.8/site-packages/aiohttp/connector.py", line 874, in _resolve_host
    addrs = await self._resolver.resolve(host, port, family=self._family)
  File "/home/itjeong/.local/lib/python3.8/site-packages/aiohttp/resolver.py", line 33, in resolve
    infos = await self._loop.getaddrinfo(
  File "/usr/lib/python3.8/asyncio/base_events.py", line 825, in getaddrinfo
    return await self.run_in_executor(
  File "/usr/lib/python3.8/concurrent/futures/thread.py", line 57, in run
    result = self.fn(*self.args, **self.kwargs)
  File "/usr/lib/python3.8/socket.py", line 918, in getaddrinfo
    for res in _socket.getaddrinfo(host, port, family, type, proto, flags):
socket.gaierror: [Errno -3] Temporary failure in name resolution

The above exception was the direct cause of the following exception:

Traceback (most recent call last):
  File "/home/itjeong/.local/lib/python3.8/site-packages/discord/client.py", line 656, in connect
    self.ws = await asyncio.wait_for(coro, timeout=60.0)
  File "/usr/lib/python3.8/asyncio/tasks.py", line 494, in wait_for
    return fut.result()
  File "/home/itjeong/.local/lib/python3.8/site-packages/discord/gateway.py", line 372, in from_client
    socket = await client.http.ws_connect(str(url))
  File "/home/itjeong/.local/lib/python3.8/site-packages/discord/http.py", line 536, in ws_connect
    return await self.__session.ws_connect(url, **kwargs)
  File "/home/itjeong/.local/lib/python3.8/site-packages/aiohttp/client.py", line 779, in _ws_connect
    resp = await self.request(
  File "/home/itjeong/.local/lib/python3.8/site-packages/aiohttp/client.py", line 536, in _request
    conn = await self._connector.connect(
  File "/home/itjeong/.local/lib/python3.8/site-packages/aiohttp/connector.py", line 540, in connect
    proto = await self._create_connection(req, traces, timeout)
  File "/home/itjeong/.local/lib/python3.8/site-packages/aiohttp/connector.py", line 901, in _create_connection
    _, proto = await self._create_direct_connection(req, traces, timeout)
  File "/home/itjeong/.local/lib/python3.8/site-packages/aiohttp/connector.py", line 1166, in _create_direct_connection
    raise ClientConnectorError(req.connection_key, exc) from exc
aiohttp.client_exceptions.ClientConnectorError: Cannot connect to host gateway-us-east1-d.discord.gg:443 ssl:default [Temporary failure in name resolution]
[2023-03-15 21:35:39] [ERROR   ] discord.client: Attempting a reconnect in 644.86s
Traceback (most recent call last):
  File "/home/itjeong/.local/lib/python3.8/site-packages/aiohttp/connector.py", line 1152, in _create_direct_connection
    hosts = await asyncio.shield(host_resolved)
  File "/home/itjeong/.local/lib/python3.8/site-packages/aiohttp/connector.py", line 874, in _resolve_host
    addrs = await self._resolver.resolve(host, port, family=self._family)
  File "/home/itjeong/.local/lib/python3.8/site-packages/aiohttp/resolver.py", line 33, in resolve
    infos = await self._loop.getaddrinfo(
  File "/usr/lib/python3.8/asyncio/base_events.py", line 825, in getaddrinfo
    return await self.run_in_executor(
  File "/usr/lib/python3.8/concurrent/futures/thread.py", line 57, in run
    result = self.fn(*self.args, **self.kwargs)
  File "/usr/lib/python3.8/socket.py", line 918, in getaddrinfo
    for res in _socket.getaddrinfo(host, port, family, type, proto, flags):
socket.gaierror: [Errno -3] Temporary failure in name resolution

The above exception was the direct cause of the following exception:

Traceback (most recent call last):
  File "/home/itjeong/.local/lib/python3.8/site-packages/discord/client.py", line 656, in connect
    self.ws = await asyncio.wait_for(coro, timeout=60.0)
  File "/usr/lib/python3.8/asyncio/tasks.py", line 494, in wait_for
    return fut.result()
  File "/home/itjeong/.local/lib/python3.8/site-packages/discord/gateway.py", line 372, in from_client
    socket = await client.http.ws_connect(str(url))
  File "/home/itjeong/.local/lib/python3.8/site-packages/discord/http.py", line 536, in ws_connect
    return await self.__session.ws_connect(url, **kwargs)
  File "/home/itjeong/.local/lib/python3.8/site-packages/aiohttp/client.py", line 779, in _ws_connect
    resp = await self.request(
  File "/home/itjeong/.local/lib/python3.8/site-packages/aiohttp/client.py", line 536, in _request
    conn = await self._connector.connect(
  File "/home/itjeong/.local/lib/python3.8/site-packages/aiohttp/connector.py", line 540, in connect
    proto = await self._create_connection(req, traces, timeout)
  File "/home/itjeong/.local/lib/python3.8/site-packages/aiohttp/connector.py", line 901, in _create_connection
    _, proto = await self._create_direct_connection(req, traces, timeout)
  File "/home/itjeong/.local/lib/python3.8/site-packages/aiohttp/connector.py", line 1166, in _create_direct_connection
    raise ClientConnectorError(req.connection_key, exc) from exc
aiohttp.client_exceptions.ClientConnectorError: Cannot connect to host gateway-us-east1-d.discord.gg:443 ssl:default [Temporary failure in name resolution]
[2023-03-15 21:46:34] [ERROR   ] discord.client: Attempting a reconnect in 773.81s
Traceback (most recent call last):
  File "/home/itjeong/.local/lib/python3.8/site-packages/aiohttp/connector.py", line 1152, in _create_direct_connection
    hosts = await asyncio.shield(host_resolved)
  File "/home/itjeong/.local/lib/python3.8/site-packages/aiohttp/connector.py", line 874, in _resolve_host
    addrs = await self._resolver.resolve(host, port, family=self._family)
  File "/home/itjeong/.local/lib/python3.8/site-packages/aiohttp/resolver.py", line 33, in resolve
    infos = await self._loop.getaddrinfo(
  File "/usr/lib/python3.8/asyncio/base_events.py", line 825, in getaddrinfo
    return await self.run_in_executor(
  File "/usr/lib/python3.8/concurrent/futures/thread.py", line 57, in run
    result = self.fn(*self.args, **self.kwargs)
  File "/usr/lib/python3.8/socket.py", line 918, in getaddrinfo
    for res in _socket.getaddrinfo(host, port, family, type, proto, flags):
socket.gaierror: [Errno -3] Temporary failure in name resolution

The above exception was the direct cause of the following exception:

Traceback (most recent call last):
  File "/home/itjeong/.local/lib/python3.8/site-packages/discord/client.py", line 656, in connect
    self.ws = await asyncio.wait_for(coro, timeout=60.0)
  File "/usr/lib/python3.8/asyncio/tasks.py", line 494, in wait_for
    return fut.result()
  File "/home/itjeong/.local/lib/python3.8/site-packages/discord/gateway.py", line 372, in from_client
    socket = await client.http.ws_connect(str(url))
  File "/home/itjeong/.local/lib/python3.8/site-packages/discord/http.py", line 536, in ws_connect
    return await self.__session.ws_connect(url, **kwargs)
  File "/home/itjeong/.local/lib/python3.8/site-packages/aiohttp/client.py", line 779, in _ws_connect
    resp = await self.request(
  File "/home/itjeong/.local/lib/python3.8/site-packages/aiohttp/client.py", line 536, in _request
    conn = await self._connector.connect(
  File "/home/itjeong/.local/lib/python3.8/site-packages/aiohttp/connector.py", line 540, in connect
    proto = await self._create_connection(req, traces, timeout)
  File "/home/itjeong/.local/lib/python3.8/site-packages/aiohttp/connector.py", line 901, in _create_connection
    _, proto = await self._create_direct_connection(req, traces, timeout)
  File "/home/itjeong/.local/lib/python3.8/site-packages/aiohttp/connector.py", line 1166, in _create_direct_connection
    raise ClientConnectorError(req.connection_key, exc) from exc
aiohttp.client_exceptions.ClientConnectorError: Cannot connect to host gateway-us-east1-d.discord.gg:443 ssl:default [Temporary failure in name resolution]
[2023-03-15 21:59:38] [ERROR   ] discord.client: Attempting a reconnect in 578.10s
Traceback (most recent call last):
  File "/home/itjeong/.local/lib/python3.8/site-packages/aiohttp/connector.py", line 1152, in _create_direct_connection
    hosts = await asyncio.shield(host_resolved)
  File "/home/itjeong/.local/lib/python3.8/site-packages/aiohttp/connector.py", line 874, in _resolve_host
    addrs = await self._resolver.resolve(host, port, family=self._family)
  File "/home/itjeong/.local/lib/python3.8/site-packages/aiohttp/resolver.py", line 33, in resolve
    infos = await self._loop.getaddrinfo(
  File "/usr/lib/python3.8/asyncio/base_events.py", line 825, in getaddrinfo
    return await self.run_in_executor(
  File "/usr/lib/python3.8/concurrent/futures/thread.py", line 57, in run
    result = self.fn(*self.args, **self.kwargs)
  File "/usr/lib/python3.8/socket.py", line 918, in getaddrinfo
    for res in _socket.getaddrinfo(host, port, family, type, proto, flags):
socket.gaierror: [Errno -3] Temporary failure in name resolution

The above exception was the direct cause of the following exception:

Traceback (most recent call last):
  File "/home/itjeong/.local/lib/python3.8/site-packages/discord/client.py", line 656, in connect
    self.ws = await asyncio.wait_for(coro, timeout=60.0)
  File "/usr/lib/python3.8/asyncio/tasks.py", line 494, in wait_for
    return fut.result()
  File "/home/itjeong/.local/lib/python3.8/site-packages/discord/gateway.py", line 372, in from_client
    socket = await client.http.ws_connect(str(url))
  File "/home/itjeong/.local/lib/python3.8/site-packages/discord/http.py", line 536, in ws_connect
    return await self.__session.ws_connect(url, **kwargs)
  File "/home/itjeong/.local/lib/python3.8/site-packages/aiohttp/client.py", line 779, in _ws_connect
    resp = await self.request(
  File "/home/itjeong/.local/lib/python3.8/site-packages/aiohttp/client.py", line 536, in _request
    conn = await self._connector.connect(
  File "/home/itjeong/.local/lib/python3.8/site-packages/aiohttp/connector.py", line 540, in connect
    proto = await self._create_connection(req, traces, timeout)
  File "/home/itjeong/.local/lib/python3.8/site-packages/aiohttp/connector.py", line 901, in _create_connection
    _, proto = await self._create_direct_connection(req, traces, timeout)
  File "/home/itjeong/.local/lib/python3.8/site-packages/aiohttp/connector.py", line 1166, in _create_direct_connection
    raise ClientConnectorError(req.connection_key, exc) from exc
aiohttp.client_exceptions.ClientConnectorError: Cannot connect to host gateway-us-east1-d.discord.gg:443 ssl:default [Temporary failure in name resolution]
[2023-03-15 22:09:26] [ERROR   ] discord.client: Attempting a reconnect in 484.39s
Traceback (most recent call last):
  File "/home/itjeong/.local/lib/python3.8/site-packages/aiohttp/connector.py", line 1152, in _create_direct_connection
    hosts = await asyncio.shield(host_resolved)
  File "/home/itjeong/.local/lib/python3.8/site-packages/aiohttp/connector.py", line 874, in _resolve_host
    addrs = await self._resolver.resolve(host, port, family=self._family)
  File "/home/itjeong/.local/lib/python3.8/site-packages/aiohttp/resolver.py", line 33, in resolve
    infos = await self._loop.getaddrinfo(
  File "/usr/lib/python3.8/asyncio/base_events.py", line 825, in getaddrinfo
    return await self.run_in_executor(
  File "/usr/lib/python3.8/concurrent/futures/thread.py", line 57, in run
    result = self.fn(*self.args, **self.kwargs)
  File "/usr/lib/python3.8/socket.py", line 918, in getaddrinfo
    for res in _socket.getaddrinfo(host, port, family, type, proto, flags):
socket.gaierror: [Errno -3] Temporary failure in name resolution

The above exception was the direct cause of the following exception:

Traceback (most recent call last):
  File "/home/itjeong/.local/lib/python3.8/site-packages/discord/client.py", line 656, in connect
    self.ws = await asyncio.wait_for(coro, timeout=60.0)
  File "/usr/lib/python3.8/asyncio/tasks.py", line 494, in wait_for
    return fut.result()
  File "/home/itjeong/.local/lib/python3.8/site-packages/discord/gateway.py", line 372, in from_client
    socket = await client.http.ws_connect(str(url))
  File "/home/itjeong/.local/lib/python3.8/site-packages/discord/http.py", line 536, in ws_connect
    return await self.__session.ws_connect(url, **kwargs)
  File "/home/itjeong/.local/lib/python3.8/site-packages/aiohttp/client.py", line 779, in _ws_connect
    resp = await self.request(
  File "/home/itjeong/.local/lib/python3.8/site-packages/aiohttp/client.py", line 536, in _request
    conn = await self._connector.connect(
  File "/home/itjeong/.local/lib/python3.8/site-packages/aiohttp/connector.py", line 540, in connect
    proto = await self._create_connection(req, traces, timeout)
  File "/home/itjeong/.local/lib/python3.8/site-packages/aiohttp/connector.py", line 901, in _create_connection
    _, proto = await self._create_direct_connection(req, traces, timeout)
  File "/home/itjeong/.local/lib/python3.8/site-packages/aiohttp/connector.py", line 1166, in _create_direct_connection
    raise ClientConnectorError(req.connection_key, exc) from exc
aiohttp.client_exceptions.ClientConnectorError: Cannot connect to host gateway-us-east1-d.discord.gg:443 ssl:default [Temporary failure in name resolution]
[2023-03-15 22:17:40] [ERROR   ] discord.client: Attempting a reconnect in 153.32s
Traceback (most recent call last):
  File "/home/itjeong/.local/lib/python3.8/site-packages/aiohttp/connector.py", line 1152, in _create_direct_connection
    hosts = await asyncio.shield(host_resolved)
  File "/home/itjeong/.local/lib/python3.8/site-packages/aiohttp/connector.py", line 874, in _resolve_host
    addrs = await self._resolver.resolve(host, port, family=self._family)
  File "/home/itjeong/.local/lib/python3.8/site-packages/aiohttp/resolver.py", line 33, in resolve
    infos = await self._loop.getaddrinfo(
  File "/usr/lib/python3.8/asyncio/base_events.py", line 825, in getaddrinfo
    return await self.run_in_executor(
  File "/usr/lib/python3.8/concurrent/futures/thread.py", line 57, in run
    result = self.fn(*self.args, **self.kwargs)
  File "/usr/lib/python3.8/socket.py", line 918, in getaddrinfo
    for res in _socket.getaddrinfo(host, port, family, type, proto, flags):
socket.gaierror: [Errno -3] Temporary failure in name resolution

The above exception was the direct cause of the following exception:

Traceback (most recent call last):
  File "/home/itjeong/.local/lib/python3.8/site-packages/discord/client.py", line 656, in connect
    self.ws = await asyncio.wait_for(coro, timeout=60.0)
  File "/usr/lib/python3.8/asyncio/tasks.py", line 494, in wait_for
    return fut.result()
  File "/home/itjeong/.local/lib/python3.8/site-packages/discord/gateway.py", line 372, in from_client
    socket = await client.http.ws_connect(str(url))
  File "/home/itjeong/.local/lib/python3.8/site-packages/discord/http.py", line 536, in ws_connect
    return await self.__session.ws_connect(url, **kwargs)
  File "/home/itjeong/.local/lib/python3.8/site-packages/aiohttp/client.py", line 779, in _ws_connect
    resp = await self.request(
  File "/home/itjeong/.local/lib/python3.8/site-packages/aiohttp/client.py", line 536, in _request
    conn = await self._connector.connect(
  File "/home/itjeong/.local/lib/python3.8/site-packages/aiohttp/connector.py", line 540, in connect
    proto = await self._create_connection(req, traces, timeout)
  File "/home/itjeong/.local/lib/python3.8/site-packages/aiohttp/connector.py", line 901, in _create_connection
    _, proto = await self._create_direct_connection(req, traces, timeout)
  File "/home/itjeong/.local/lib/python3.8/site-packages/aiohttp/connector.py", line 1166, in _create_direct_connection
    raise ClientConnectorError(req.connection_key, exc) from exc
aiohttp.client_exceptions.ClientConnectorError: Cannot connect to host gateway-us-east1-d.discord.gg:443 ssl:default [Temporary failure in name resolution]
[2023-03-15 22:20:24] [ERROR   ] discord.client: Attempting a reconnect in 572.29s
Traceback (most recent call last):
  File "/home/itjeong/.local/lib/python3.8/site-packages/aiohttp/connector.py", line 1152, in _create_direct_connection
    hosts = await asyncio.shield(host_resolved)
  File "/home/itjeong/.local/lib/python3.8/site-packages/aiohttp/connector.py", line 874, in _resolve_host
    addrs = await self._resolver.resolve(host, port, family=self._family)
  File "/home/itjeong/.local/lib/python3.8/site-packages/aiohttp/resolver.py", line 33, in resolve
    infos = await self._loop.getaddrinfo(
  File "/usr/lib/python3.8/asyncio/base_events.py", line 825, in getaddrinfo
    return await self.run_in_executor(
  File "/usr/lib/python3.8/concurrent/futures/thread.py", line 57, in run
    result = self.fn(*self.args, **self.kwargs)
  File "/usr/lib/python3.8/socket.py", line 918, in getaddrinfo
    for res in _socket.getaddrinfo(host, port, family, type, proto, flags):
socket.gaierror: [Errno -3] Temporary failure in name resolution

The above exception was the direct cause of the following exception:

Traceback (most recent call last):
  File "/home/itjeong/.local/lib/python3.8/site-packages/discord/client.py", line 656, in connect
    self.ws = await asyncio.wait_for(coro, timeout=60.0)
  File "/usr/lib/python3.8/asyncio/tasks.py", line 494, in wait_for
    return fut.result()
  File "/home/itjeong/.local/lib/python3.8/site-packages/discord/gateway.py", line 372, in from_client
    socket = await client.http.ws_connect(str(url))
  File "/home/itjeong/.local/lib/python3.8/site-packages/discord/http.py", line 536, in ws_connect
    return await self.__session.ws_connect(url, **kwargs)
  File "/home/itjeong/.local/lib/python3.8/site-packages/aiohttp/client.py", line 779, in _ws_connect
    resp = await self.request(
  File "/home/itjeong/.local/lib/python3.8/site-packages/aiohttp/client.py", line 536, in _request
    conn = await self._connector.connect(
  File "/home/itjeong/.local/lib/python3.8/site-packages/aiohttp/connector.py", line 540, in connect
    proto = await self._create_connection(req, traces, timeout)
  File "/home/itjeong/.local/lib/python3.8/site-packages/aiohttp/connector.py", line 901, in _create_connection
    _, proto = await self._create_direct_connection(req, traces, timeout)
  File "/home/itjeong/.local/lib/python3.8/site-packages/aiohttp/connector.py", line 1166, in _create_direct_connection
    raise ClientConnectorError(req.connection_key, exc) from exc
aiohttp.client_exceptions.ClientConnectorError: Cannot connect to host gateway-us-east1-d.discord.gg:443 ssl:default [Temporary failure in name resolution]
[2023-03-15 22:29:57] [INFO    ] discord.gateway: Shard ID None session has been invalidated.
[2023-03-15 22:30:02] [INFO    ] discord.gateway: Shard ID None has connected to Gateway (Session ID: bfc3b86dd41f9db63a4d88f71622eb56).
[2023-03-16 01:58:23] [INFO    ] discord.gateway: Shard ID None has successfully RESUMED session bfc3b86dd41f9db63a4d88f71622eb56.
[2023-03-16 02:28:54] [INFO    ] discord.gateway: Shard ID None has successfully RESUMED session bfc3b86dd41f9db63a4d88f71622eb56.
[2023-03-16 04:00:40] [INFO    ] discord.gateway: Shard ID None has successfully RESUMED session bfc3b86dd41f9db63a4d88f71622eb56.
[2023-03-16 06:38:04] [INFO    ] discord.gateway: Shard ID None has successfully RESUMED session bfc3b86dd41f9db63a4d88f71622eb56.
[2023-03-16 09:06:57] [INFO    ] discord.gateway: Shard ID None has successfully RESUMED session bfc3b86dd41f9db63a4d88f71622eb56.
[2023-03-16 10:20:30] [INFO    ] discord.gateway: Shard ID None has successfully RESUMED session bfc3b86dd41f9db63a4d88f71622eb56.
[2023-03-16 12:39:47] [INFO    ] discord.gateway: Shard ID None has successfully RESUMED session bfc3b86dd41f9db63a4d88f71622eb56.
[2023-03-16 12:43:55] [INFO    ] discord.gateway: Shard ID None has successfully RESUMED session bfc3b86dd41f9db63a4d88f71622eb56.
